Workbook

Sheet Data
A1: VisitNum | B1: VisitNum_Month | C1: Date | D1: ClassLength | E1: Splat | F1: Calories | G1: Avg HR | H1: Max HR | I1: Gray Min | J1: Blue Min | K1: Green Min | L1: Orange Min | M1: Red Min | N1: Location | O1: Time | P1: Trainer | Q1: DaysSince | R1: Mon_Yr | S1: ClassType | T1: Weekday | U1: Twelve_or_Above | V1: Gray_Perc | W1: Blue_Perc | X1: Green_Perc | Y1: Orange_Perc | Z1: Red_Perc | AA1: Monthly_Cost | AB1: Cost_Per_Class | AC1: Calories_Month | AD1: SplatPts_Month | AE1: Year | AF1: ExtraExpenses | AG1: Goal | AH1: Cal_Min | AI1: Morn_Even | AJ1: Week_Month | AK1: Month | AL1: Calories_Splat | AM1: Visits_Studio | AN1: State | AO1: State_Perc | AP1: Latitude | AQ1: Longitude | AR1: Visits_Trainer | AS1: ScaleSplat | AT1: ScaleCalories | AU1: ScaleMin | AV1: ScaleCombine | AW1: CompositeScore | AX1: MONYEAR | AY1: Quarter
A2: 1 | B2: =COUNTIF(R:R,R2) -> 3 | C2: 43538 | D2: =SUM(Table2[[#This Row],[Gray Min]:[Red Min]]) -> 55 | E2: 1 | F2: 565 | G2: 122 | H2: 165 | I2: 18 | J2: 20 | K2: 16 | L2: 1 | M2: 0 | N2: Dunn Lorring, VA | O2: 4:30PM | P2: Audrey | R2: =MONTH(C2)&"-"&YEAR(C2) -> 3-2019 | T2: =IF(WEEKDAY(C2)=1,"Sunday",IF(WEEKDAY(C2)=2,"Monday",IF(WEEKDAY(C2)=3,"Tuesday",IF(WEEKDAY(C2)=4,"Wednesday",IF(WEEKDAY(C2)=5,"Thursday",IF(WEEKDAY(C2)=6,"Friday","Saturday")))))) -> Thursday | U2: =IF(E2>=12,1,0) -> 0 | V2: =IFERROR(Table2[[#This Row],[Gray Min]]/Table2[[#This Row],[ClassLength]],"") -> 0.32727273 | W2: =IFERROR(Table2[[#This Row],[Blue Min]]/Table2[[#This Row],[ClassLength]],"") -> 0.36363636 | X2: =IFERROR(Table2[[#This Row],[Green Min]]/Table2[[#This Row],[ClassLength]],"") -> 0.29090909 | Y2: =IFERROR(Table2[[#This Row],[Orange Min]]/Table2[[#This Row],[ClassLength]],"") -> 0.018181818 | Z2: =IFERROR(Table2[[#This Row],[Red Min]]/Table2[[#This Row],[ClassLength]],"") -> 0 | AA2: 133.49 | AB2: =AA2/3 -> 44.496667 | AC2: =AVERAGEIF(R:R,R2,F:F) -> 596.33333 | AD2: =AVERAGEIF(R:R,R2,E:E) -> 1.3333333 | AE2: =YEAR(C2) -> 2019 | AG2: 3 | AH2: =F2/D2 -> 10.272727 | AI2: =RIGHT(O2,2) -> PM | AJ2: =R2&"-"&WEEKNUM(C2,1)-WEEKNUM(DATE(YEAR(C2),MONTH(C2),1),1)+1 -> 3-2019-3 | AK2: =MONTH(C2) -> 3 | AL2: =IFERROR(Table2[[#This Row],[Calories]]/Table2[[#This Row],[Splat]],"") -> 565 | AM2: =COUNTIF(N$2:$N$938,N2) -> 35 | AN2: =VLOOKUP(N2,'Helpful Tables'!A:D,4,FALSE) -> Virginia | AO2: =COUNTIF(AN:AN,Table2[[#This Row],[State]])/COUNTA(AN:AN) -> 0.056503198 | AP2: =VLOOKUP(N2,'Helpful Tables'!A:B,2,FALSE) -> 38.881885 | AQ2: =VLOOKUP(N2,'Helpful Tables'!A:C,3,FALSE) -> -77.229702 | AR2: =COUNTIF(P$2:$P$938,P2) -> 13 | AS2: {=_xlfn.IFS(E2<6,((E2/D2)*60)*0.5,AND(E2>=6,E2<9),((E2/D2)*60)*0.75,AND(E2>=9,E2<=11),((E2/D2)*60)*0.9,AND(E2=12),((E2/D2)*60)*1,AND(E2>=13,E2<=15),((E2/D2)*60)*1.2,AND(E2>=16,E2<=19),((E2/D2)*60)*1.5,E2>=20,((E2/D2)*60)*1.8)} -> 0.54545455 | AT2: {=_xlfn.IFS(F2<550,((F2/D2)*60)*0.5,AND(F2>=550,F2<575),((F2/D2)*60)*0.75,AND(F2>=575,F2<600),((F2/D2)*60)*0.9,AND(F2=600),((F2/D2)*60)*1,AND(F2>=601,F2<=625),((F2/D2)*60)*1.2,AND(F2>=626,F2<=650),((F2/D2)*60)*1.5,F2>=651,((F2/D2)*60)*1.8)} -> 462.27273 | AU2: =(I2*-1.2)+(J2*-1.1)+(K2*1.2)+(L2*1.3)+(M2*1.5) -> -23.1 | AV2: =(AS2*0.4)+(AT2*0.4)+(AU2*0.2) -> 180.50727 | AW2: =PERCENTRANK(AV:AV,AV2)*100 -> 10.7 | AX2: =_xlfn.CONCAT(TEXT(C2,"mmm"),"-",AE2) -> Mar-2019 | AY2: =ROUNDUP(Table2[[#This Row],[Month]]/3,0) -> 1
A3: 2 | B3: =COUNTIF(R:R,R3) -> 3 | C3: 43545 | D3: =SUM(Table2[[#This Row],[Gray Min]:[Red Min]]) -> 58 | E3: 1 | F3: 586 | G3: 121 | H3: 167 | I3: 16 | J3: 17 | K3: 24 | L3: 1 | M3: 0 | N3: Dunn Lorring, VA | O3: 4:30PM | P3: Audrey | Q3: =C3-C2 -> 7 | R3: =MONTH(C3)&"-"&YEAR(C3) -> 3-2019 | T3: =IF(WEEKDAY(C3)=1,"Sunday",IF(WEEKDAY(C3)=2,"Monday",IF(WEEKDAY(C3)=3,"Tuesday",IF(WEEKDAY(C3)=4,"Wednesday",IF(WEEKDAY(C3)=5,"Thursday",IF(WEEKDAY(C3)=6,"Friday","Saturday")))))) -> Thursday | U3: =IF(E3>=12,1,0) -> 0 | V3: =IFERROR(Table2[[#This Row],[Gray Min]]/Table2[[#This Row],[ClassLength]],"") -> 0.27586207 | W3: =IFERROR(Table2[[#This Row],[Blue Min]]/Table2[[#This Row],[ClassLength]],"") -> 0.29310345 | X3: =IFERROR(Table2[[#This Row],[Green Min]]/Table2[[#This Row],[ClassLength]],"") -> 0.4137931 | Y3: =IFERROR(Table2[[#This Row],[Orange Min]]/Table2[[#This Row],[ClassLength]],"") -> 0.017241379 | Z3: =IFERROR(Table2[[#This Row],[Red Min]]/Table2[[#This Row],[ClassLength]],"") -> 0 | AA3: 133.49 | AB3: =AA3/3 -> 44.496667 | AC3: =AVERAGEIF(R:R,R3,F:F) -> 596.33333 | AD3: =AVERAGEIF(R:R,R3,E:E) -> 1.3333333 | AE3: =YEAR(C3) -> 2019 | AG3: 3 | AH3: =F3/D3 -> 10.103448 | AI3: =RIGHT(O3,2) -> PM | AJ3: =R3&"-"&WEEKNUM(C3,1)-WEEKNUM(DATE(YEAR(C3),MONTH(C3),1),1)+1 -> 3-2019-4 | AK3: =MONTH(C3) -> 3 | AL3: =IFERROR(Table2[[#This Row],[Calories]]/Table2[[#This Row],[Splat]],"") -> 586 | AM3: =COUNTIF(N$2:$N$938,N3) -> 35 | AN3: =VLOOKUP(N3,'Helpful Tables'!A:D,4,FALSE) -> Virginia | AO3: =COUNTIF(AN:AN,Table2[[#This Row],[State]])/COUNTA(AN:AN) -> 0.056503198 | AP3: =VLOOKUP(N3,'Helpful Tables'!A:B,2,FALSE) -> 38.881885 | AQ3: =VLOOKUP(N3,'Helpful Tables'!A:C,3,FALSE) -> -77.229702 | AR3: =COUNTIF(P$2:$P$938,P3) -> 13 | AS3: {=_xlfn.IFS(E3<6,((E3/D3)*60)*0.5,AND(E3>=6,E3<9),((E3/D3)*60)*0.75,AND(E3>=9,E3<=11),((E3/D3)*60)*0.9,AND(E3=12),((E3/D3)*60)*1,AND(E3>=13,E3<=15),((E3/D3)*60)*1.2,AND(E3>=16,E3<=19),((E3/D3)*60)*1.5,E3>=20,((E3/D3)*60)*1.8)} -> 0.51724138 | AT3: {=_xlfn.IFS(F3<550,((F3/D3)*60)*0.5,AND(F3>=550,F3<575),((F3/D3)*60)*0.75,AND(F3>=575,F3<600),((F3/D3)*60)*0.9,AND(F3=600),((F3/D3)*60)*1,AND(F3>=601,F3<=625),((F3/D3)*60)*1.2,AND(F3>=626,F3<=650),((F3/D3)*60)*1.5,F3>=651,((F3/D3)*60)*1.8)} -> 545.58621 | AU3: =(I3*-1.2)+(J3*-1.1)+(K3*1.2)+(L3*1.3)+(M3*1.5) -> -7.8 | AV3: =(AS3*0.4)+(AT3*0.4)+(AU3*0.2) -> 216.88138 | AW3: =PERCENTRANK(AV:AV,AV3)*100 -> 15.8 | AX3: =_xlfn.CONCAT(TEXT(C3,"mmm"),"-",AE3) -> Mar-2019 | AY3: =ROUNDUP(Table2[[#This Row],[Month]]/3,0) -> 1
A4: 3 | B4: =COUNTIF(R:R,R4) -> 3 | C4: 43552 | D4: =SUM(Table2[[#This Row],[Gray Min]:[Red Min]]) -> 57 | E4: 2 | F4: 638 | G4: 128 | H4: 169 | I4: 13 | J4: 17 | K4: 25 | L4: 2 | M4: 0 | N4: Dunn Lorring, VA | O4: 4:30PM | P4: Kandace | Q4: =C4-C3 -> 7 | R4: =MONTH(C4)&"-"&YEAR(C4) -> 3-2019 | T4: =IF(WEEKDAY(C4)=1,"Sunday",IF(WEEKDAY(C4)=2,"Monday",IF(WEEKDAY(C4)=3,"Tuesday",IF(WEEKDAY(C4)=4,"Wednesday",IF(WEEKDAY(C4)=5,"Thursday",IF(WEEKDAY(C4)=6,"Friday","Saturday")))))) -> Thursday | U4: =IF(E4>=12,1,0) -> 0 | V4: =IFERROR(Table2[[#This Row],[Gray Min]]/Table2[[#This Row],[ClassLength]],"") -> 0.22807018 | W4: =IFERROR(Table2[[#This Row],[Blue Min]]/Table2[[#This Row],[ClassLength]],"") -> 0.29824561 | X4: =IFERROR(Table2[[#This Row],[Green Min]]/Table2[[#This Row],[ClassLength]],"") -> 0.43859649 | Y4: =IFERROR(Table2[[#This Row],[Orange Min]]/Table2[[#This Row],[ClassLength]],"") -> 0.035087719 | Z4: =IFERROR(Table2[[#This Row],[Red Min]]/Table2[[#This Row],[ClassLength]],"") -> 0 | AA4: 133.49 | AB4: =AA4/3 -> 44.496667 | AC4: =AVERAGEIF(R:R,R4,F:F) -> 596.33333 | AD4: =AVERAGEIF(R:R,R4,E:E) -> 1.3333333 | AE4: =YEAR(C4) -> 2019 | AF4: 83.74 | AG4: 3 | AH4: =F4/D4 -> 11.192982 | AI4: =RIGHT(O4,2) -> PM | AJ4: =R4&"-"&WEEKNUM(C4,1)-WEEKNUM(DATE(YEAR(C4),MONTH(C4),1),1)+1 -> 3-2019-5 | AK4: =MONTH(C4) -> 3 | AL4: =IFERROR(Table2[[#This Row],[Calories]]/Table2[[#This Row],[Splat]],"") -> 319 | AM4: =COUNTIF(N$2:$N$938,N4) -> 35 | AN4: =VLOOKUP(N4,'Helpful Tables'!A:D,4,FALSE) -> Virginia | AO4: =COUNTIF(AN:AN,Table2[[#This Row],[State]])/COUNTA(AN:AN) -> 0.056503198 | AP4: =VLOOKUP(N4,'Helpful Tables'!A:B,2,FALSE) -> 38.881885 | AQ4: =VLOOKUP(N4,'Helpful Tables'!A:C,3,FALSE) -> -77.229702 | AR4: =COUNTIF(P$2:$P$938,P4) -> 10 | AS4: {=_xlfn.IFS(E4<6,((E4/D4)*60)*0.5,AND(E4>=6,E4<9),((E4/D4)*60)*0.75,AND(E4>=9,E4<=11),((E4/D4)*60)*0.9,AND(E4=12),((E4/D4)*60)*1,AND(E4>=13,E4<=15),((E4/D4)*60)*1.2,AND(E4>=16,E4<=19),((E4/D4)*60)*1.5,E4>=20,((E4/D4)*60)*1.8)} -> 1.0526316 | AT4: {=_xlfn.IFS(F4<550,((F4/D4)*60)*0.5,AND(F4>=550,F4<575),((F4/D4)*60)*0.75,AND(F4>=575,F4<600),((F4/D4)*60)*0.9,AND(F4=600),((F4/D4)*60)*1,AND(F4>=601,F4<=625),((F4/D4)*60)*1.2,AND(F4>=626,F4<=650),((F4/D4)*60)*1.5,F4>=651,((F4/D4)*60)*1.8)} -> 1007.3684 | AU4: =(I4*-1.2)+(J4*-1.1)+(K4*1.2)+(L4*1.3)+(M4*1.5) -> -1.7 | AV4: =(AS4*0.4)+(AT4*0.4)+(AU4*0.2) -> 403.02842 | AW4: =PERCENTRANK(AV:AV,AV4)*100 -> 54.6 | AX4: =_xlfn.CONCAT(TEXT(C4,"mmm"),"-",AE4) -> Mar-2019 | AY4: =ROUNDUP(Table2[[#This Row],[Month]]/3,0) -> 1
A5: 4 | B5: =COUNTIF(R:R,R5) -> 3 | C5: 43559 | D5: =SUM(Table2[[#This Row],[Gray Min]:[Red Min]]) -> 57 | E5: 8 | F5: 601 | G5: 124 | H5: 169 | I5: 25.9 | J5: 5.2666667 | K5: 17.533333 | L5: 8.3 | M5: 0 | N5: Dunn Lorring, VA | O5: 4:30PM | P5: Audrey | Q5: =C5-C4 -> 7 | R5: =MONTH(C5)&"-"&YEAR(C5) -> 4-2019 | T5: =IF(WEEKDAY(C5)=1,"Sunday",IF(WEEKDAY(C5)=2,"Monday",IF(WEEKDAY(C5)=3,"Tuesday",IF(WEEKDAY(C5)=4,"Wednesday",IF(WEEKDAY(C5)=5,"Thursday",IF(WEEKDAY(C5)=6,"Friday","Saturday")))))) -> Thursday | U5: =IF(E5>=12,1,0) -> 0 | V5: =IFERROR(Table2[[#This Row],[Gray Min]]/Table2[[#This Row],[ClassLength]],"") -> 0.45438596 | W5: =IFERROR(Table2[[#This Row],[Blue Min]]/Table2[[#This Row],[ClassLength]],"") -> 0.092397661 | X5: =IFERROR(Table2[[#This Row],[Green Min]]/Table2[[#This Row],[ClassLength]],"") -> 0.30760234 | Y5: =IFERROR(Table2[[#This Row],[Orange Min]]/Table2[[#This Row],[ClassLength]],"") -> 0.14561404 | Z5: =IFERROR(Table2[[#This Row],[Red Min]]/Table2[[#This Row],[ClassLength]],"") -> 0 | AA5: 49.75 | AB5: =AA5/3 -> 16.583333 | AC5: =AVERAGEIF(R:R,R5,F:F) -> 563.66667 | AD5: =AVERAGEIF(R:R,R5,E:E) -> 8.3333333 | AE5: =YEAR(C5) -> 2019 | AG5: 3 | AH5: =F5/D5 -> 10.54386 | AI5: =RIGHT(O5,2) -> PM | AJ5: =R5&"-"&WEEKNUM(C5,1)-WEEKNUM(DATE(YEAR(C5),MONTH(C5),1),1)+1 -> 4-2019-1 | AK5: =MONTH(C5) -> 4 | AL5: =IFERROR(Table2[[#This Row],[Calories]]/Table2[[#This Row],[Splat]],"") -> 75.125 | AM5: =COUNTIF(N$2:$N$938,N5) -> 35 | AN5: =VLOOKUP(N5,'Helpful Tables'!A:D,4,FALSE) -> Virginia | AO5: =COUNTIF(AN:AN,Table2[[#This Row],[State]])/COUNTA(AN:AN) -> 0.056503198 | AP5: =VLOOKUP(N5,'Helpful Tables'!A:B,2,FALSE) -> 38.881885 | AQ5: =VLOOKUP(N5,'Helpful Tables'!A:C,3,FALSE) -> -77.229702 | AR5: =COUNTIF(P$2:$P$938,P5) -> 13 | AS5: {=_xlfn.IFS(E5<6,((E5/D5)*60)*0.5,AND(E5>=6,E5<9),((E5/D5)*60)*0.75,AND(E5>=9,E5<=11),((E5/D5)*60)*0.9,AND(E5=12),((E5/D5)*60)*1,AND(E5>=13,E5<=15),((E5/D5)*60)*1.2,AND(E5>=16,E5<=19),((E5/D5)*60)*1.5,E5>=20,((E5/D5)*60)*1.8)} -> 6.3157895 | AT5: {=_xlfn.IFS(F5<550,((F5/D5)*60)*0.5,AND(F5>=550,F5<575),((F5/D5)*60)*0.75,AND(F5>=575,F5<600),((F5/D5)*60)*0.9,AND(F5=600),((F5/D5)*60)*1,AND(F5>=601,F5<=625),((F5/D5)*60)*1.2,AND(F5>=626,F5<=650),((F5/D5)*60)*1.5,F5>=651,((F5/D5)*60)*1.8)} -> 759.15789 | AU5: =(I5*-1.2)+(J5*-1.1)+(K5*1.2)+(L5*1.3)+(M5*1.5) -> -5.0433333 | AV5: =(AS5*0.4)+(AT5*0.4)+(AU5*0.2) -> 305.18081 | AW5: =PERCENTRANK(AV:AV,AV5)*100 -> 29.2 | AX5: =_xlfn.CONCAT(TEXT(C5,"mmm"),"-",AE5) -> Apr-2019 | AY5: =ROUNDUP(Table2[[#This Row],[Month]]/3,0) -> 2
A6: 5 | B6: =COUNTIF(R:R,R6) -> 3 | C6: 43564 | D6: =SUM(Table2[[#This Row],[Gray Min]:[Red Min]]) -> 57.033333 | E6: 9 | F6: 542 | G6: 117 | H6: 177 | I6: 26.65 | J6: 13.916667 | K6: 7.4166667 | L6: 7.2666667 | M6: 1.7833333 | N6: Dunn Lorring, VA | O6: 4:30PM | P6: Kacie | Q6: =C6-C5 -> 5 | R6: =MONTH(C6)&"-"&YEAR(C6) -> 4-2019 | T6: =IF(WEEKDAY(C6)=1,"Sunday",IF(WEEKDAY(C6)=2,"Monday",IF(WEEKDAY(C6)=3,"Tuesday",IF(WEEKDAY(C6)=4,"Wednesday",IF(WEEKDAY(C6)=5,"Thursday",IF(WEEKDAY(C6)=6,"Friday","Saturday")))))) -> Tuesday | U6: =IF(E6>=12,1,0) -> 0 | V6: =IFERROR(Table2[[#This Row],[Gray Min]]/Table2[[#This Row],[ClassLength]],"") -> 0.4672706 | W6: =IFERROR(Table2[[#This Row],[Blue Min]]/Table2[[#This Row],[ClassLength]],"") -> 0.24400935 | X6: =IFERROR(Table2[[#This Row],[Green Min]]/Table2[[#This Row],[ClassLength]],"") -> 0.13004091 | Y6: =IFERROR(Table2[[#This Row],[Orange Min]]/Table2[[#This Row],[ClassLength]],"") -> 0.12741087 | Z6: =IFERROR(Table2[[#This Row],[Red Min]]/Table2[[#This Row],[ClassLength]],"") -> 0.031268264 | AA6: 49.75 | AB6: =AA6/3 -> 16.583333 | AC6: =AVERAGEIF(R:R,R6,F:F) -> 563.66667 | AD6: =AVERAGEIF(R:R,R6,E:E) -> 8.3333333 | AE6: =YEAR(C6) -> 2019 | AG6: 3 | AH6: =F6/D6 -> 9.5032145 | AI6: =RIGHT(O6,2) -> PM | AJ6: =R6&"-"&WEEKNUM(C6,1)-WEEKNUM(DATE(YEAR(C6),MONTH(C6),1),1)+1 -> 4-2019-2 | AK6: =MONTH(C6) -> 4 | AL6: =IFERROR(Table2[[#This Row],[Calories]]/Table2[[#This Row],[Splat]],"") -> 60.222222 | AM6: =COUNTIF(N$2:$N$938,N6) -> 35 | AN6: =VLOOKUP(N6,'Helpful Tables'!A:D,4,FALSE) -> Virginia | AO6: =COUNTIF(AN:AN,Table2[[#This Row],[State]])/COUNTA(AN:AN) -> 0.056503198 | AP6: =VLOOKUP(N6,'Helpful Tables'!A:B,2,FALSE) -> 38.881885 | AQ6: =VLOOKUP(N6,'Helpful Tables'!A:C,3,FALSE) -> -77.229702 | AR6: =COUNTIF(P$2:$P$938,P6) -> 2 | AS6: {=_xlfn.IFS(E6<6,((E6/D6)*60)*0.5,AND(E6>=6,E6<9),((E6/D6)*60)*0.75,AND(E6>=9,E6<=11),((E6/D6)*60)*0.9,AND(E6=12),((E6/D6)*60)*1,AND(E6>=13,E6<=15),((E6/D6)*60)*1.2,AND(E6>=16,E6<=19),((E6/D6)*60)*1.5,E6>=20,((E6/D6)*60)*1.8)} -> 8.5213326 | AT6: {=_xlfn.IFS(F6<550,((F6/D6)*60)*0.5,AND(F6>=550,F6<575),((F6/D6)*60)*0.75,AND(F6>=575,F6<600),((F6/D6)*60)*0.9,AND(F6=600),((F6/D6)*60)*1,AND(F6>=601,F6<=625),((F6/D6)*60)*1.2,AND(F6>=626,F6<=650),((F6/D6)*60)*1.5,F6>=651,((F6/D6)*60)*1.8)} -> 285.09643 | AU6: =(I6*-1.2)+(J6*-1.1)+(K6*1.2)+(L6*1.3)+(M6*1.5) -> -26.266667 | AV6: =(AS6*0.4)+(AT6*0.4)+(AU6*0.2) -> 112.19377 | AW6: =PERCENTRANK(AV:AV,AV6)*100 -> 4.5 | AX6: =_xlfn.CONCAT(TEXT(C6,"mmm"),"-",AE6) -> Apr-2019 | AY6: =ROUNDUP(Table2[[#This Row],[Month]]/3,0) -> 2
A7: 6 | B7: =COUNTIF(R:R,R7) -> 3 | C7: 43573 | D7: =SUM(Table2[[#This Row],[Gray Min]:[Red Min]]) -> 57 | E7: 8 | F7: 548 | G7: 118 | H7: 167 | I7: 29.066667 | J7: 8.0333333 | K7: 12.25 | L7: 7.65 | M7: 0 | N7: Dunn Lorring, VA | O7: 4:30PM | P7: Audrey | Q7: =C7-C6 -> 9 | R7: =MONTH(C7)&"-"&YEAR(C7) -> 4-2019 | T7: =IF(WEEKDAY(C7)=1,"Sunday",IF(WEEKDAY(C7)=2,"Monday",IF(WEEKDAY(C7)=3,"Tuesday",IF(WEEKDAY(C7)=4,"Wednesday",IF(WEEKDAY(C7)=5,"Thursday",IF(WEEKDAY(C7)=6,"Friday","Saturday")))))) -> Thursday | U7: =IF(E7>=12,1,0) -> 0 | V7: =IFERROR(Table2[[#This Row],[Gray Min]]/Table2[[#This Row],[ClassLength]],"") -> 0.50994152 | W7: =IFERROR(Table2[[#This Row],[Blue Min]]/Table2[[#This Row],[ClassLength]],"") -> 0.14093567 | X7: =IFERROR(Table2[[#This Row],[Green Min]]/Table2[[#This Row],[ClassLength]],"") -> 0.21491228 | Y7: =IFERROR(Table2[[#This Row],[Orange Min]]/Table2[[#This Row],[ClassLength]],"") -> 0.13421053 | Z7: =IFERROR(Table2[[#This Row],[Red Min]]/Table2[[#This Row],[ClassLength]],"") -> 0 | AA7: 49.75 | AB7: =AA7/3 -> 16.583333 | AC7: =AVERAGEIF(R:R,R7,F:F) -> 563.66667 | AD7: =AVERAGEIF(R:R,R7,E:E) -> 8.3333333 | AE7: =YEAR(C7) -> 2019 | AG7: 3 | AH7: =F7/D7 -> 9.6140351 | AI7: =RIGHT(O7,2) -> PM | AJ7: =R7&"-"&WEEKNUM(C7,1)-WEEKNUM(DATE(YEAR(C7),MONTH(C7),1),1)+1 -> 4-2019-3 | AK7: =MONTH(C7) -> 4 | AL7: =IFERROR(Table2[[#This Row],[Calories]]/Table2[[#This Row],[Splat]],"") -> 68.5 | AM7: =COUNTIF(N$2:$N$938,N7) -> 35 | AN7: =VLOOKUP(N7,'Helpful Tables'!A:D,4,FALSE) -> Virginia | AO7: =COUNTIF(AN:AN,Table2[[#This Row],[State]])/COUNTA(AN:AN) -> 0.056503198 | AP7: =VLOOKUP(N7,'Helpful Tables'!A:B,2,FALSE) -> 38.881885 | AQ7: =VLOOKUP(N7,'Helpful Tables'!A:C,3,FALSE) -> -77.229702 | AR7: =COUNTIF(P$2:$P$938,P7) -> 13 | AS7: {=_xlfn.IFS(E7<6,((E7/D7)*60)*0.5,AND(E7>=6,E7<9),((E7/D7)*60)*0.75,AND(E7>=9,E7<=11),((E7/D7)*60)*0.9,AND(E7=12),((E7/D7)*60)*1,AND(E7>=13,E7<=15),((E7/D7)*60)*1.2,AND(E7>=16,E7<=19),((E7/D7)*60)*1.5,E7>=20,((E7/D7)*60)*1.8)} -> 6.3157895 | AT7: {=_xlfn.IFS(F7<550,((F7/D7)*60)*0.5,AND(F7>=550,F7<575),((F7/D7)*60)*0.75,AND(F7>=575,F7<600),((F7/D7)*60)*0.9,AND(F7=600),((F7/D7)*60)*1,AND(F7>=601,F7<=625),((F7/D7)*60)*1.2,AND(F7>=626,F7<=650),((F7/D7)*60)*1.5,F7>=651,((F7/D7)*60)*1.8)} -> 288.42105 | AU7: =(I7*-1.2)+(J7*-1.1)+(K7*1.2)+(L7*1.3)+(M7*1.5) -> -19.071667 | AV7: =(AS7*0.4)+(AT7*0.4)+(AU7*0.2) -> 114.0804 | AW7: =PERCENTRANK(AV:AV,AV7)*100 -> 5.2 | AX7: =_xlfn.CONCAT(TEXT(C7,"mmm"),"-",AE7) -> Apr-2019 | AY7: =ROUNDUP(Table2[[#This Row],[Month]]/3,0) -> 2
A8: 7 | B8: =COUNTIF(R:R,R8) -> 4 | C8: 43587 | D8: =SUM(Table2[[#This Row],[Gray Min]:[Red Min]]) -> 53 | E8: 8 | F8: 534 | G8: 121 | H8: 177 | I8: 24.566667 | J8: 12.333333 | K8: 7.65 | L8: 6.1666667 | M8: 2.2833333 | N8: Dunn Lorring, VA | O8: 4:30PM | P8: Audrey | Q8: =C8-C7 -> 14 | R8: =MONTH(C8)&"-"&YEAR(C8) -> 5-2019 | T8: =IF(WEEKDAY(C8)=1,"Sunday",IF(WEEKDAY(C8)=2,"Monday",IF(WEEKDAY(C8)=3,"Tuesday",IF(WEEKDAY(C8)=4,"Wednesday",IF(WEEKDAY(C8)=5,"Thursday",IF(WEEKDAY(C8)=6,"Friday","Saturday")))))) -> Thursday | U8: =IF(E8>=12,1,0) -> 0 | V8: =IFERROR(Table2[[#This Row],[Gray Min]]/Table2[[#This Row],[ClassLength]],"") -> 0.46352201 | W8: =IFERROR(Table2[[#This Row],[Blue Min]]/Table2[[#This Row],[ClassLength]],"") -> 0.2327044 | X8: =IFERROR(Table2[[#This Row],[Green Min]]/Table2[[#This Row],[ClassLength]],"") -> 0.14433962 | Y8: =IFERROR(Table2[[#This Row],[Orange Min]]/Table2[[#This Row],[ClassLength]],"") -> 0.1163522 | Z8: =IFERROR(Table2[[#This Row],[Red Min]]/Table2[[#This Row],[ClassLength]],"") -> 0.043081761 | AA8: 66.33 | AB8: =AA8/4 -> 16.5825 | AC8: =AVERAGEIF(R:R,R8,F:F) -> 641 | AD8: =AVERAGEIF(R:R,R8,E:E) -> 10.5 | AE8: =YEAR(C8) -> 2019 | AG8: 3 | AH8: =F8/D8 -> 10.075472 | AI8: =RIGHT(O8,2) -> PM | AJ8: =R8&"-"&WEEKNUM(C8,1)-WEEKNUM(DATE(YEAR(C8),MONTH(C8),1),1)+1 -> 5-2019-1 | AK8: =MONTH(C8) -> 5 | AL8: =IFERROR(Table2[[#This Row],[Calories]]/Table2[[#This Row],[Splat]],"") -> 66.75 | AM8: =COUNTIF(N$2:$N$938,N8) -> 35 | AN8: =VLOOKUP(N8,'Helpful Tables'!A:D,4,FALSE) -> Virginia | AO8: =COUNTIF(AN:AN,Table2[[#This Row],[State]])/COUNTA(AN:AN) -> 0.056503198 | AP8: =VLOOKUP(N8,'Helpful Tables'!A:B,2,FALSE) -> 38.881885 | AQ8: =VLOOKUP(N8,'Helpful Tables'!A:C,3,FALSE) -> -77.229702 | AR8: =COUNTIF(P$2:$P$938,P8) -> 13 | AS8: {=_xlfn.IFS(E8<6,((E8/D8)*60)*0.5,AND(E8>=6,E8<9),((E8/D8)*60)*0.75,AND(E8>=9,E8<=11),((E8/D8)*60)*0.9,AND(E8=12),((E8/D8)*60)*1,AND(E8>=13,E8<=15),((E8/D8)*60)*1.2,AND(E8>=16,E8<=19),((E8/D8)*60)*1.5,E8>=20,((E8/D8)*60)*1.8)} -> 6.7924528 | AT8: {=_xlfn.IFS(F8<550,((F8/D8)*60)*0.5,AND(F8>=550,F8<575),((F8/D8)*60)*0.75,AND(F8>=575,F8<600),((F8/D8)*60)*0.9,AND(F8=600),((F8/D8)*60)*1,AND(F8>=601,F8<=625),((F8/D8)*60)*1.2,AND(F8>=626,F8<=650),((F8/D8)*60)*1.5,F8>=651,((F8/D8)*60)*1.8)} -> 302.26415 | AU8: =(I8*-1.2)+(J8*-1.1)+(K8*1.2)+(L8*1.3)+(M8*1.5) -> -22.425 | AV8: =(AS8*0.4)+(AT8*0.4)+(AU8*0.2) -> 119.13764 | AW8: =PERCENTRANK(AV:AV,AV8)*100 -> 6.6 | AX8: =_xlfn.CONCAT(TEXT(C8,"mmm"),"-",AE8) -> May-2019 | AY8: =ROUNDUP(Table2[[#This Row],[Month]]/3,0) -> 2
A9: 8 | B9: =COUNTIF(R:R,R9) -> 4 | C9: 43599 | D9: =SUM(Table2[[#This Row],[Gray Min]:[Red Min]]) -> 58 | E9: 12 | F9: 649 | G9: 129 | H9: 177 | I9: 20.466667 | J9: 10.083333 | K9: 16.233333 | L9: 9.6833333 | M9: 1.5333333 | N9: Dunn Lorring, VA | O9: 4:30PM | P9: Kacie | Q9: =C9-C8 -> 12 | R9: =MONTH(C9)&"-"&YEAR(C9) -> 5-2019 | T9: =IF(WEEKDAY(C9)=1,"Sunday",IF(WEEKDAY(C9)=2,"Monday",IF(WEEKDAY(C9)=3,"Tuesday",IF(WEEKDAY(C9)=4,"Wednesday",IF(WEEKDAY(C9)=5,"Thursday",IF(WEEKDAY(C9)=6,"Friday","Saturday")))))) -> Tuesday | U9: =IF(E9>=12,1,0) -> 1 | V9: =IFERROR(Table2[[#This Row],[Gray Min]]/Table2[[#This Row],[ClassLength]],"") -> 0.35287356 | W9: =IFERROR(Table2[[#This Row],[Blue Min]]/Table2[[#This Row],[ClassLength]],"") -> 0.17385057 | X9: =IFERROR(Table2[[#This Row],[Green Min]]/Table2[[#This Row],[ClassLength]],"") -> 0.27988506 | Y9: =IFERROR(Table2[[#This Row],[Orange Min]]/Table2[[#This Row],[ClassLength]],"") -> 0.16695402 | Z9: =IFERROR(Table2[[#This Row],[Red Min]]/Table2[[#This Row],[ClassLength]],"") -> 0.026436782 | AA9: 66.33 | AB9: =AA9/4 -> 16.5825 | AC9: =AVERAGEIF(R:R,R9,F:F) -> 641 | AD9: =AVERAGEIF(R:R,R9,E:E) -> 10.5 | AE9: =YEAR(C9) -> 2019 | AG9: 3 | AH9: =F9/D9 -> 11.189655 | AI9: =RIGHT(O9,2) -> PM | AJ9: =R9&"-"&WEEKNUM(C9,1)-WEEKNUM(DATE(YEAR(C9),MONTH(C9),1),1)+1 -> 5-2019-3 | AK9: =MONTH(C9) -> 5 | AL9: =IFERROR(Table2[[#This Row],[Calories]]/Table2[[#This Row],[Splat]],"") -> 54.083333 | AM9: =COUNTIF(N$2:$N$938,N9) -> 35 | AN9: =VLOOKUP(N9,'Helpful Tables'!A:D,4,FALSE) -> Virginia | AO9: =COUNTIF(AN:AN,Table2[[#This Row],[State]])/COUNTA(AN:AN) -> 0.056503198 | AP9: =VLOOKUP(N9,'Helpful Tables'!A:B,2,FALSE) -> 38.881885 | AQ9: =VLOOKUP(N9,'Helpful Tables'!A:C,3,FALSE) -> -77.229702 | AR9: =COUNTIF(P$2:$P$938,P9) -> 2 | AS9: {=_xlfn.IFS(E9<6,((E9/D9)*60)*0.5,AND(E9>=6,E9<9),((E9/D9)*60)*0.75,AND(E9>=9,E9<=11),((E9/D9)*60)*0.9,AND(E9=12),((E9/D9)*60)*1,AND(E9>=13,E9<=15),((E9/D9)*60)*1.2,AND(E9>=16,E9<=19),((E9/D9)*60)*1.5,E9>=20,((E9/D9)*60)*1.8)} -> 12.413793 | AT9: {=_xlfn.IFS(F9<550,((F9/D9)*60)*0.5,AND(F9>=550,F9<575),((F9/D9)*60)*0.75,AND(F9>=575,F9<600),((F9/D9)*60)*0.9,AND(F9=600),((F9/D9)*60)*1,AND(F9>=601,F9<=625),((F9/D9)*60)*1.2,AND(F9>=626,F9<=650),((F9/D9)*60)*1.5,F9>=651,((F9/D9)*60)*1.8)} -> 1007.069 | AU9: =(I9*-1.2)+(J9*-1.1)+(K9*1.2)+(L9*1.3)+(M9*1.5) -> -1.2833333 | AV9: =(AS9*0.4)+(AT9*0.4)+(AU9*0.2) -> 407.53644 | AW9: =PERCENTRANK(AV:AV,AV9)*100 -> 57.3 | AX9: =_xlfn.CONCAT(TEXT(C9,"mmm"),"-",AE9) -> May-2019 | AY9: =ROUNDUP(Table2[[#This Row],[Month]]/3,0) -> 2
A10: 9 | B10: =COUNTIF(R:R,R10) -> 4 | C10: 43608 | D10: =SUM(Table2[[#This Row],[Gray Min]:[Red Min]]) -> 59.05 | E10: 13 | F10: 709 | G10: 134 | H10: 177 | I10: 9.6666667 | J10: 15.383333 | K10: 21.316667 | L10: 12.583333 | M10: 0.1 | N10: Dunn Lorring, VA | O10: 4:30PM | P10: Audrey | Q10: =C10-C9 -> 9 | R10: =MONTH(C10)&"-"&YEAR(C10) -> 5-2019 | T10: =IF(WEEKDAY(C10)=1,"Sunday",IF(WEEKDAY(C10)=2,"Monday",IF(WEEKDAY(C10)=3,"Tuesday",IF(WEEKDAY(C10)=4,"Wednesday",IF(WEEKDAY(C10)=5,"Thursday",IF(WEEKDAY(C10)=6,"Friday","Saturday")))))) -> Thursday | U10: =IF(E10>=12,1,0) -> 1 | V10: =IFERROR(Table2[[#This Row],[Gray Min]]/Table2[[#This Row],[ClassLength]],"") -> 0.16370308 | W10: =IFERROR(Table2[[#This Row],[Blue Min]]/Table2[[#This Row],[ClassLength]],"") -> 0.26051369 | X10: =IFERROR(Table2[[#This Row],[Green Min]]/Table2[[#This Row],[ClassLength]],"") -> 0.36099351 | Y10: =IFERROR(Table2[[#This Row],[Orange Min]]/Table2[[#This Row],[ClassLength]],"") -> 0.21309625 | Z10: =IFERROR(Table2[[#This Row],[Red Min]]/Table2[[#This Row],[ClassLength]],"") -> 0.0016934801 | AA10: 66.33 | AB10: =AA10/4 -> 16.5825 | AC10: =AVERAGEIF(R:R,R10,F:F) -> 641 | AD10: =AVERAGEIF(R:R,R10,E:E) -> 10.5 | AE10: =YEAR(C10) -> 2019 | AG10: 3 | AH10: =F10/D10 -> 12.006774 | AI10: =RIGHT(O10,2) -> PM | AJ10: =R10&"-"&WEEKNUM(C10,1)-WEEKNUM(DATE(YEAR(C10),MONTH(C10),1),1)+1 -> 5-2019-4 | AK10: =MONTH(C10) -> 5 | AL10: =IFERROR(Table2[[#This Row],[Calories]]/Table2[[#This Row],[Splat]],"") -> 54.538462 | AM10: =COUNTIF(N$2:$N$938,N10) -> 35 | AN10: =VLOOKUP(N10,'Helpful Tables'!A:D,4,FALSE) -> Virginia | AO10: =COUNTIF(AN:AN,Table2[[#This Row],[State]])/COUNTA(AN:AN) -> 0.056503198 | AP10: =VLOOKUP(N10,'Helpful Tables'!A:B,2,FALSE) -> 38.881885 | AQ10: =VLOOKUP(N10,'Helpful Tables'!A:C,3,FALSE) -> -77.229702 | AR10: =COUNTIF(P$2:$P$938,P10) -> 13 | AS10: {=_xlfn.IFS(E10<6,((E10/D10)*60)*0.5,AND(E10>=6,E10<9),((E10/D10)*60)*0.75,AND(E10>=9,E10<=11),((E10/D10)*60)*0.9,AND(E10=12),((E10/D10)*60)*1,AND(E10>=13,E10<=15),((E10/D10)*60)*1.2,AND(E10>=16,E10<=19),((E10/D10)*60)*1.5,E10>=20,((E10/D10)*60)*1.8)} -> 15.850974 | AT10: {=_xlfn.IFS(F10<550,((F10/D10)*60)*0.5,AND(F10>=550,F10<575),((F10/D10)*60)*0.75,AND(F10>=575,F10<600),((F10/D10)*60)*0.9,AND(F10=600),((F10/D10)*60)*1,AND(F10>=601,F10<=625),((F10/D10)*60)*1.2,AND(F10>=626,F10<=650),((F10/D10)*60)*1.5,F10>=651,((F10/D10)*60)*1.8)} -> 1296.7316 | AU10: =(I10*-1.2)+(J10*-1.1)+(K10*1.2)+(L10*1.3)+(M10*1.5) -> 13.566667 | AV10: =(AS10*0.4)+(AT10*0.4)+(AU10*0.2) -> 527.74636 | AW10: =PERCENTRANK(AV:AV,AV10)*100 -> 93.1 | AX10: =_xlfn.CONCAT(TEXT(C10,"mmm"),"-",AE10) -> May-2019 | AY10: =ROUNDUP(Table2[[#This Row],[Month]]/3,0) -> 2
A11: 10 | B11: =COUNTIF(R:R,R11) -> 4 | C11: 43615 | D11: =SUM(Table2[[#This Row],[Gray Min]:[Red Min]]) -> 56.3 | E11: 9 | F11: 672 | G11: 134 | H11: 177 | I11: 6.0833333 | J11: 21.183333 | K11: 19.533333 | L11: 8.25 | M11: 1.25 | N11: Dunn Lorring, VA | O11: 4:30PM | P11: Audrey | Q11: =C11-C10 -> 7 | R11: =MONTH(C11)&"-"&YEAR(C11) -> 5-2019 | T11: =IF(WEEKDAY(C11)=1,"Sunday",IF(WEEKDAY(C11)=2,"Monday",IF(WEEKDAY(C11)=3,"Tuesday",IF(WEEKDAY(C11)=4,"Wednesday",IF(WEEKDAY(C11)=5,"Thursday",IF(WEEKDAY(C11)=6,"Friday","Saturday")))))) -> Thursday | U11: =IF(E11>=12,1,0) -> 0 | V11: =IFERROR(Table2[[#This Row],[Gray Min]]/Table2[[#This Row],[ClassLength]],"") -> 0.1080521 | W11: =IFERROR(Table2[[#This Row],[Blue Min]]/Table2[[#This Row],[ClassLength]],"") -> 0.37625814 | X11: =IFERROR(Table2[[#This Row],[Green Min]]/Table2[[#This Row],[ClassLength]],"") -> 0.34695086 | Y11: =IFERROR(Table2[[#This Row],[Orange Min]]/Table2[[#This Row],[ClassLength]],"") -> 0.14653641 | Z11: =IFERROR(Table2[[#This Row],[Red Min]]/Table2[[#This Row],[ClassLength]],"") -> 0.022202487 | AA11: 66.33 | AB11: =AA11/4 -> 16.5825 | AC11: =AVERAGEIF(R:R,R11,F:F) -> 641 | AD11: =AVERAGEIF(R:R,R11,E:E) -> 10.5 | AE11: =YEAR(C11) -> 2019 | AG11: 3 | AH11: =F11/D11 -> 11.936057 | AI11: =RIGHT(O11,2) -> PM | AJ11: =R11&"-"&WEEKNUM(C11,1)-WEEKNUM(DATE(YEAR(C11),MONTH(C11),1),1)+1 -> 5-2019-5 | AK11: =MONTH(C11) -> 5 | AL11: =IFERROR(Table2[[#This Row],[Calories]]/Table2[[#This Row],[Splat]],"") -> 74.666667 | AM11: =COUNTIF(N$2:$N$938,N11) -> 35 | AN11: =VLOOKUP(N11,'Helpful Tables'!A:D,4,FALSE) -> Virginia | AO11: =COUNTIF(AN:AN,Table2[[#This Row],[State]])/COUNTA(AN:AN) -> 0.056503198 | AP11: =VLOOKUP(N11,'Helpful Tables'!A:B,2,FALSE) -> 38.881885 | AQ11: =VLOOKUP(N11,'Helpful Tables'!A:C,3,FALSE) -> -77.229702 | AR11: =COUNTIF(P$2:$P$938,P11) -> 13 | AS11: {=_xlfn.IFS(E11<6,((E11/D11)*60)*0.5,AND(E11>=6,E11<9),((E11/D11)*60)*0.75,AND(E11>=9,E11<=11),((E11/D11)*60)*0.9,AND(E11=12),((E11/D11)*60)*1,AND(E11>=13,E11<=15),((E11/D11)*60)*1.2,AND(E11>=16,E11<=19),((E11/D11)*60)*1.5,E11>=20,((E11/D11)*60)*1.8)} -> 8.6323268 | AT11: {=_xlfn.IFS(F11<550,((F11/D11)*60)*0.5,AND(F11>=550,F11<575),((F11/D11)*60)*0.75,AND(F11>=575,F11<600),((F11/D11)*60)*0.9,AND(F11=600),((F11/D11)*60)*1,AND(F11>=601,F11<=625),((F11/D11)*60)*1.2,AND(F11>=626,F11<=650),((F11/D11)*60)*1.5,F11>=651,((F11/D11)*60)*1.8)} -> 1289.0941 | AU11: =(I11*-1.2)+(J11*-1.1)+(K11*1.2)+(L11*1.3)+(M11*1.5) -> 5.4383333 | AV11: =(AS11*0.4)+(AT11*0.4)+(AU11*0.2) -> 520.17825 | AW11: =PERCENTRANK(AV:AV,AV11)*100 -> 90.2 | AX11: =_xlfn.CONCAT(TEXT(C11,"mmm"),"-",AE11) -> May-2019 | AY11: =ROUNDUP(Table2[[#This Row],[Month]]/3,0) -> 2
A12: 11 | B12: =COUNTIF(R:R,R12) -> 10 | C12: 43622 | D12: =SUM(Table2[[#This Row],[Gray Min]:[Red Min]]) -> 60.55 | E12: 14 | F12: 701 | G12: 131 | H12: 172 | I12: 17.783333 | J12: 13.9 | K12: 14.7 | L12: 14.116667 | M12: 0.05 | N12: Dunn Lorring, VA | O12: 4:30PM | P12: Audrey | Q12: =C12-C11 -> 7 | R12: =MONTH(C12)&"-"&YEAR(C12) -> 6-2019 | T12: =IF(WEEKDAY(C12)=1,"Sunday",IF(WEEKDAY(C12)=2,"Monday",IF(WEEKDAY(C12)=3,"Tuesday",IF(WEEKDAY(C12)=4,"Wednesday",IF(WEEKDAY(C12)=5,"Thursday",IF(WEEKDAY(C12)=6,"Friday","Saturday")))))) -> Thursday | U12: =IF(E12>=12,1,0) -> 1 | V12: =IFERROR(Table2[[#This Row],[Gray Min]]/Table2[[#This Row],[ClassLength]],"") -> 0.29369667 | W12: =IFERROR(Table2[[#This Row],[Blue Min]]/Table2[[#This Row],[ClassLength]],"") -> 0.22956235 | X12: =IFERROR(Table2[[#This Row],[Green Min]]/Table2[[#This Row],[ClassLength]],"") -> 0.24277457 | Y12: =IFERROR(Table2[[#This Row],[Orange Min]]/Table2[[#This Row],[ClassLength]],"") -> 0.23314066 | Z12: =IFERROR(Table2[[#This Row],[Red Min]]/Table2[[#This Row],[ClassLength]],"") -> 0.00082576383 | AA12: 33.17 | AB12: =AA12/2 -> 16.585 | AC12: =AVERAGEIF(R:R,R12,F:F) -> 669.6 | AD12: =AVERAGEIF(R:R,R12,E:E) -> 10.2 | AE12: =YEAR(C12) -> 2019 | AG12: 12 | AH12: =F12/D12 -> 11.577209 | AI12: =RIGHT(O12,2) -> PM | AJ12: =R12&"-"&WEEKNUM(C12,1)-WEEKNUM(DATE(YEAR(C12),MONTH(C12),1),1)+1 -> 6-2019-2 | AK12: =MONTH(C12) -> 6 | AL12: =IFERROR(Table2[[#This Row],[Calories]]/Table2[[#This Row],[Splat]],"") -> 50.071429 | AM12: =COUNTIF(N$2:$N$938,N12) -> 35 | AN12: =VLOOKUP(N12,'Helpful Tables'!A:D,4,FALSE) -> Virginia | AO12: =COUNTIF(AN:AN,Table2[[#This Row],[State]])/COUNTA(AN:AN) -> 0.056503198 | AP12: =VLOOKUP(N12,'Helpful Tables'!A:B,2,FALSE) -> 38.881885 | AQ12: =VLOOKUP(N12,'Helpful Tables'!A:C,3,FALSE) -> -77.229702 | AR12: =COUNTIF(P$2:$P$938,P12) -> 13 | AS12: {=_xlfn.IFS(E12<6,((E12/D12)*60)*0.5,AND(E12>=6,E12<9),((E12/D12)*60)*0.75,AND(E12>=9,E12<=11),((E12/D12)*60)*0.9,AND(E12=12),((E12/D12)*60)*1,AND(E12>=13,E12<=15),((E12/D12)*60)*1.2,AND(E12>=16,E12<=19),((E12/D12)*60)*1.5,E12>=20,((E12/D12)*60)*1.8)} -> 16.647399 | AT12: {=_xlfn.IFS(F12<550,((F12/D12)*60)*0.5,AND(F12>=550,F12<575),((F12/D12)*60)*0.75,AND(F12>=575,F12<600),((F12/D12)*60)*0.9,AND(F12=600),((F12/D12)*60)*1,AND(F12>=601,F12<=625),((F12/D12)*60)*1.2,AND(F12>=626,F12<=650),((F12/D12)*60)*1.5,F12>=651,((F12/D12)*60)*1.8)} -> 1250.3386 | AU12: =(I12*-1.2)+(J12*-1.1)+(K12*1.2)+(L12*1.3)+(M12*1.5) -> -0.56333333 | AV12: =(AS12*0.4)+(AT12*0.4)+(AU12*0.2) -> 506.68172 | AW12: =PERCENTRANK(AV:AV,AV12)*100 -> 83.5 | AX12: =_xlfn.CONCAT(TEXT(C12,"mmm"),"-",AE12) -> Jun-2019 | AY12: =ROUNDUP(Table2[[#This Row],[Month]]/3,0) -> 2
A13: 12 | B13: =COUNTIF(R:R,R13) -> 10 | C13: 43625 | D13: =SUM(Table2[[#This Row],[Gray Min]:[Red Min]]) -> 55.816667 | E13: 8 | F13: 667 | G13: 134 | H13: 187 | I13: 7.2 | J13: 17.866667 | K13: 22.65 | L13: 8.0833333 | M13: 0.016666667 | N13: Rosslyn, VA | O13: 10:30AM | P13: Courtney1 | Q13: =C13-C12 -> 3 | R13: =MONTH(C13)&"-"&YEAR(C13) -> 6-2019 | T13: =IF(WEEKDAY(C13)=1,"Sunday",IF(WEEKDAY(C13)=2,"Monday",IF(WEEKDAY(C13)=3,"Tuesday",IF(WEEKDAY(C13)=4,"Wednesday",IF(WEEKDAY(C13)=5,"Thursday",IF(WEEKDAY(C13)=6,"Friday","Saturday")))))) -> Sunday | U13: =IF(E13>=12,1,0) -> 0 | V13: =IFERROR(Table2[[#This Row],[Gray Min]]/Table2[[#This Row],[ClassLength]],"") -> 0.12899373 | W13: =IFERROR(Table2[[#This Row],[Blue Min]]/Table2[[#This Row],[ClassLength]],"") -> 0.32009555 | X13: =IFERROR(Table2[[#This Row],[Green Min]]/Table2[[#This Row],[ClassLength]],"") -> 0.40579277 | Y13: =IFERROR(Table2[[#This Row],[Orange Min]]/Table2[[#This Row],[ClassLength]],"") -> 0.14481935 | Z13: =IFERROR(Table2[[#This Row],[Red Min]]/Table2[[#This Row],[ClassLength]],"") -> 0.0002985966 | AA13: 33.17 | AB13: =AA13/2 -> 16.585 | AC13: =AVERAGEIF(R:R,R13,F:F) -> 669.6 | AD13: =AVERAGEIF(R:R,R13,E:E) -> 10.2 | AE13: =YEAR(C13) -> 2019 | AG13: 12 | AH13: =F13/D13 -> 11.949836 | AI13: =RIGHT(O13,2) -> AM | AJ13: =R13&"-"&WEEKNUM(C13,1)-WEEKNUM(DATE(YEAR(C13),MONTH(C13),1),1)+1 -> 6-2019-3 | AK13: =MONTH(C13) -> 6 | AL13: =IFERROR(Table2[[#This Row],[Calories]]/Table2[[#This Row],[Splat]],"") -> 83.375 | AM13: =COUNTIF(N$2:$N$938,N13) -> 9 | AN13: =VLOOKUP(N13,'Helpful Tables'!A:D,4,FALSE) -> Virginia | AO13: =COUNTIF(AN:AN,Table2[[#This Row],[State]])/COUNTA(AN:AN) -> 0.056503198 | AP13: =VLOOKUP(N13,'Helpful Tables'!A:B,2,FALSE) -> 38.894025 | AQ13: =VLOOKUP(N13,'Helpful Tables'!A:C,3,FALSE) -> -77.078213 | AR13: =COUNTIF(P$2:$P$938,P13) -> 1 | AS13: {=_xlfn.IFS(E13<6,((E13/D13)*60)*0.5,AND(E13>=6,E13<9),((E13/D13)*60)*0.75,AND(E13>=9,E13<=11),((E13/D13)*60)*0.9,AND(E13=12),((E13/D13)*60)*1,AND(E13>=13,E13<=15),((E13/D13)*60)*1.2,AND(E13>=16,E13<=19),((E13/D13)*60)*1.5,E13>=20,((E13/D13)*60)*1.8)} -> 6.4496865 | AT13: {=_xlfn.IFS(F13<550,((F13/D13)*60)*0.5,AND(F13>=550,F13<575),((F13/D13)*60)*0.75,AND(F13>=575,F13<600),((F13/D13)*60)*0.9,AND(F13=600),((F13/D13)*60)*1,AND(F13>=601,F13<=625),((F13/D13)*60)*1.2,AND(F13>=626,F13<=650),((F13/D13)*60)*1.5,F13>=651,((F13/D13)*60)*1.8)} -> 1290.5823 | AU13: =(I13*-1.2)+(J13*-1.1)+(K13*1.2)+(L13*1.3)+(M13*1.5) -> 9.42 | AV13: =(AS13*0.4)+(AT13*0.4)+(AU13*0.2) -> 520.69678 | AW13: =PERCENTRANK(AV:AV,AV13)*100 -> 90.5 | AX13: =_xlfn.CONCAT(TEXT(C13,"mmm"),"-",AE13) -> Jun-2019 | AY13: =ROUNDUP(Table2[[#This Row],[Month]]/3,0) -> 2
A14: 13 | B14: =COUNTIF(R:R,R14) -> 10 | C14: 43631 | D14: =SUM(Table2[[#This Row],[Gray Min]:[Red Min]]) -> 54.716667 | E14: 10 | F14: 622 | G14: 130 | H14: 175 | I14: 14.483333 | J14: 16.783333 | K14: 13.233333 | L14: 9.0833333 | M14: 1.1333333 | N14: 14th Street, DC | O14: 11:30AM | P14: Tiffany | Q14: =C14-C13 -> 6 | R14: =MONTH(C14)&"-"&YEAR(C14) -> 6-2019 | T14: =IF(WEEKDAY(C14)=1,"Sunday",IF(WEEKDAY(C14)=2,"Monday",IF(WEEKDAY(C14)=3,"Tuesday",IF(WEEKDAY(C14)=4,"Wednesday",IF(WEEKDAY(C14)=5,"Thursday",IF(WEEKDAY(C14)=6,"Friday","Saturday")))))) -> Saturday | U14: =IF(E14>=12,1,0) -> 0 | V14: =IFERROR(Table2[[#This Row],[Gray Min]]/Table2[[#This Row],[ClassLength]],"") -> 0.26469692 | W14: =IFERROR(Table2[[#This Row],[Blue Min]]/Table2[[#This Row],[ClassLength]],"") -> 0.30673165 | X14: =IFERROR(Table2[[#This Row],[Green Min]]/Table2[[#This Row],[ClassLength]],"") -> 0.24185196 | Y14: =IFERROR(Table2[[#This Row],[Orange Min]]/Table2[[#This Row],[ClassLength]],"") -> 0.1660067 | Z14: =IFERROR(Table2[[#This Row],[Red Min]]/Table2[[#This Row],[ClassLength]],"") -> 0.020712763 | AA14: 10.6 | AB14: =AA14/1 -> 10.6 | AC14: =AVERAGEIF(R:R,R14,F:F) -> 669.6 | AD14: =AVERAGEIF(R:R,R14,E:E) -> 10.2 | AE14: =YEAR(C14) -> 2019 | AF14: 10.6 | AG14: 12 | AH14: =F14/D14 -> 11.367652 | AI14: =RIGHT(O14,2) -> AM | AJ14: =R14&"-"&WEEKNUM(C14,1)-WEEKNUM(DATE(YEAR(C14),MONTH(C14),1),1)+1 -> 6-2019-3 | AK14: =MONTH(C14) -> 6 | AL14: =IFERROR(Table2[[#This Row],[Calories]]/Table2[[#This Row],[Splat]],"") -> 62.2 | AM14: =COUNTIF(N$2:$N$938,N14) -> 48 | AN14: =VLOOKUP(N14,'Helpful Tables'!A:D,4,FALSE) -> Washington, DC | AO14: =COUNTIF(AN:AN,Table2[[#This Row],[State]])/COUNTA(AN:AN) -> 0.54904051 | AP14: =VLOOKUP(N14,'Helpful Tables'!A:B,2,FALSE) -> 38.916487 | AQ14: =VLOOKUP(N14,'Helpful Tables'!A:C,3,FALSE) -> -77.031514 | AR14: =COUNTIF(P$2:$P$938,P14) -> 30 | AS14: {=_xlfn.IFS(E14<6,((E14/D14)*60)*0.5,AND(E14>=6,E14<9),((E14/D14)*60)*0.75,AND(E14>=9,E14<=11),((E14/D14)*60)*0.9,AND(E14=12),((E14/D14)*60)*1,AND(E14>=13,E14<=15),((E14/D14)*60)*1.2,AND(E14>=16,E14<=19),((E14/D14)*60)*1.5,E14>=20,((E14/D14)*60)*1.8)} -> 9.8690222 | AT14: {=_xlfn.IFS(F14<550,((F14/D14)*60)*0.5,AND(F14>=550,F14<575),((F14/D14)*60)*0.75,AND(F14>=575,F14<600),((F14/D14)*60)*0.9,AND(F14=600),((F14/D14)*60)*1,AND(F14>=601,F14<=625),((F14/D14)*60)*1.2,AND(F14>=626,F14<=650),((F14/D14)*60)*1.5,F14>=651,((F14/D14)*60)*1.8)} -> 818.47091 | AU14: =(I14*-1.2)+(J14*-1.1)+(K14*1.2)+(L14*1.3)+(M14*1.5) -> -6.4533333 | AV14: =(AS14*0.4)+(AT14*0.4)+(AU14*0.2) -> 330.04531 | AW14: =PERCENTRANK(AV:AV,AV14)*100 -> 40.2 | AX14: =_xlfn.CONCAT(TEXT(C14,"mmm"),"-",AE14) -> Jun-2019 | AY14: =ROUNDUP(Table2[[#This Row],[Month]]/3,0) -> 2
A15: 14 | B15: =COUNTIF(R:R,R15) -> 10 | C15: 43632 | D15: =SUM(Table2[[#This Row],[Gray Min]:[Red Min]]) -> 53.4 | E15: 13 | F15: 676 | G15: 139 | H15: 172 | I15: 6.0833333 | J15: 12.683333 | K15: 21.45 | L15: 13.166667 | M15: 0.016666667 | N15: 14th Street, DC | O15: 2:00PM | P15: Demi | Q15: =C15-C14 -> 1 | R15: =MONTH(C15)&"-"&YEAR(C15) -> 6-2019 | T15: =IF(WEEKDAY(C15)=1,"Sunday",IF(WEEKDAY(C15)=2,"Monday",IF(WEEKDAY(C15)=3,"Tuesday",IF(WEEKDAY(C15)=4,"Wednesday",IF(WEEKDAY(C15)=5,"Thursday",IF(WEEKDAY(C15)=6,"Friday","Saturday")))))) -> Sunday | U15: =IF(E15>=12,1,0) -> 1 | V15: =IFERROR(Table2[[#This Row],[Gray Min]]/Table2[[#This Row],[ClassLength]],"") -> 0.1139201 | W15: =IFERROR(Table2[[#This Row],[Blue Min]]/Table2[[#This Row],[ClassLength]],"") -> 0.23751561 | X15: =IFERROR(Table2[[#This Row],[Green Min]]/Table2[[#This Row],[ClassLength]],"") -> 0.40168539 | Y15: =IFERROR(Table2[[#This Row],[Orange Min]]/Table2[[#This Row],[ClassLength]],"") -> 0.24656679 | Z15: =IFERROR(Table2[[#This Row],[Red Min]]/Table2[[#This Row],[ClassLength]],"") -> 0.00031210987 | AA15: 10.6 | AB15: =AA15/1 -> 10.6 | AC15: =AVERAGEIF(R:R,R15,F:F) -> 669.6 | AD15: =AVERAGEIF(R:R,R15,E:E) -> 10.2 | AE15: =YEAR(C15) -> 2019 | AF15: 10.6 | AG15: 12 | AH15: =F15/D15 -> 12.659176 | AI15: =RIGHT(O15,2) -> PM | AJ15: =R15&"-"&WEEKNUM(C15,1)-WEEKNUM(DATE(YEAR(C15),MONTH(C15),1),1)+1 -> 6-2019-4 | AK15: =MONTH(C15) -> 6 | AL15: =IFERROR(Table2[[#This Row],[Calories]]/Table2[[#This Row],[Splat]],"") -> 52 | AM15: =COUNTIF(N$2:$N$938,N15) -> 48 | AN15: =VLOOKUP(N15,'Helpful Tables'!A:D,4,FALSE) -> Washington, DC | AO15: =COUNTIF(AN:AN,Table2[[#This Row],[State]])/COUNTA(AN:AN) -> 0.54904051 | AP15: =VLOOKUP(N15,'Helpful Tables'!A:B,2,FALSE) -> 38.916487 | AQ15: =VLOOKUP(N15,'Helpful Tables'!A:C,3,FALSE) -> -77.031514 | AR15: =COUNTIF(P$2:$P$938,P15) -> 12 | AS15: {=_xlfn.IFS(E15<6,((E15/D15)*60)*0.5,AND(E15>=6,E15<9),((E15/D15)*60)*0.75,AND(E15>=9,E15<=11),((E15/D15)*60)*0.9,AND(E15=12),((E15/D15)*60)*1,AND(E15>=13,E15<=15),((E15/D15)*60)*1.2,AND(E15>=16,E15<=19),((E15/D15)*60)*1.5,E15>=20,((E15/D15)*60)*1.8)} -> 17.52809 | AT15: {=_xlfn.IFS(F15<550,((F15/D15)*60)*0.5,AND(F15>=550,F15<575),((F15/D15)*60)*0.75,AND(F15>=575,F15<600),((F15/D15)*60)*0.9,AND(F15=600),((F15/D15)*60)*1,AND(F15>=601,F15<=625),((F15/D15)*60)*1.2,AND(F15>=626,F15<=650),((F15/D15)*60)*1.5,F15>=651,((F15/D15)*60)*1.8)} -> 1367.191 | AU15: =(I15*-1.2)+(J15*-1.1)+(K15*1.2)+(L15*1.3)+(M15*1.5) -> 21.63 | AV15: =(AS15*0.4)+(AT15*0.4)+(AU15*0.2) -> 558.21364 | AW15: =PERCENTRANK(AV:AV,AV15)*100 -> 98.7 | AX15: =_xlfn.CONCAT(TEXT(C15,"mmm"),"-",AE15) -> Jun-2019 | AY15: =ROUNDUP(Table2[[#This Row],[Month]]/3,0) -> 2
A16: 15 | B16: =COUNTIF(R:R,R16) -> 10 | C16: 43634 | D16: =SUM(Table2[[#This Row],[Gray Min]:[Red Min]]) -> 57.65 | E16: 11 | F16: 639 | G16: 128 | H16: 171 | I16: 19.833333 | J16: 10.483333 | K16: 16.15 | L16: 11.183333 | M16: 0 | N16: 14th Street, DC | O16: 5:30PM | P16: Tiffany | Q16: =C16-C15 -> 2 | R16: =MONTH(C16)&"-"&YEAR(C16) -> 6-2019 | T16: =IF(WEEKDAY(C16)=1,"Sunday",IF(WEEKDAY(C16)=2,"Monday",IF(WEEKDAY(C16)=3,"Tuesday",IF(WEEKDAY(C16)=4,"Wednesday",IF(WEEKDAY(C16)=5,"Thursday",IF(WEEKDAY(C16)=6,"Friday","Saturday")))))) -> Tuesday | U16: =IF(E16>=12,1,0) -> 0 | V16: =IFERROR(Table2[[#This Row],[Gray Min]]/Table2[[#This Row],[ClassLength]],"") -> 0.34403007 | W16: =IFERROR(Table2[[#This Row],[Blue Min]]/Table2[[#This Row],[ClassLength]],"") -> 0.18184446 | X16: =IFERROR(Table2[[#This Row],[Green Min]]/Table2[[#This Row],[ClassLength]],"") -> 0.28013877 | Y16: =IFERROR(Table2[[#This Row],[Orange Min]]/Table2[[#This Row],[ClassLength]],"") -> 0.1939867 | Z16: =IFERROR(Table2[[#This Row],[Red Min]]/Table2[[#This Row],[ClassLength]],"") -> 0 | AA16: 232.14 | AB16: =AA16/B16 -> 23.214 | AC16: =AVERAGEIF(R:R,R16,F:F) -> 669.6 | AD16: =AVERAGEIF(R:R,R16,E:E) -> 10.2 | AE16: =YEAR(C16) -> 2019 | AG16: 12 | AH16: =F16/D16 -> 11.084128 | AI16: =RIGHT(O16,2) -> PM | AJ16: =R16&"-"&WEEKNUM(C16,1)-WEEKNUM(DATE(YEAR(C16),MONTH(C16),1),1)+1 -> 6-2019-4 | AK16: =MONTH(C16) -> 6 | AL16: =IFERROR(Table2[[#This Row],[Calories]]/Table2[[#This Row],[Splat]],"") -> 58.090909 | AM16: =COUNTIF(N$2:$N$938,N16) -> 48 | AN16: =VLOOKUP(N16,'Helpful Tables'!A:D,4,FALSE) -> Washington, DC | AO16: =COUNTIF(AN:AN,Table2[[#This Row],[State]])/COUNTA(AN:AN) -> 0.54904051 | AP16: =VLOOKUP(N16,'Helpful Tables'!A:B,2,FALSE) -> 38.916487 | AQ16: =VLOOKUP(N16,'Helpful Tables'!A:C,3,FALSE) -> -77.031514 | AR16: =COUNTIF(P$2:$P$938,P16) -> 30 | AS16: {=_xlfn.IFS(E16<6,((E16/D16)*60)*0.5,AND(E16>=6,E16<9),((E16/D16)*60)*0.75,AND(E16>=9,E16<=11),((E16/D16)*60)*0.9,AND(E16=12),((E16/D16)*60)*1,AND(E16>=13,E16<=15),((E16/D16)*60)*1.2,AND(E16>=16,E16<=19),((E16/D16)*60)*1.5,E16>=20,((E16/D16)*60)*1.8)} -> 10.303556 | AT16: {=_xlfn.IFS(F16<550,((F16/D16)*60)*0.5,AND(F16>=550,F16<575),((F16/D16)*60)*0.75,AND(F16>=575,F16<600),((F16/D16)*60)*0.9,AND(F16=600),((F16/D16)*60)*1,AND(F16>=601,F16<=625),((F16/D16)*60)*1.2,AND(F16>=626,F16<=650),((F16/D16)*60)*1.5,F16>=651,((F16/D16)*60)*1.8)} -> 997.57155 | AU16: =(I16*-1.2)+(J16*-1.1)+(K16*1.2)+(L16*1.3)+(M16*1.5) -> -1.4133333 | AV16: =(AS16*0.4)+(AT16*0.4)+(AU16*0.2) -> 402.86738 | AW16: =PERCENTRANK(AV:AV,AV16)*100 -> 54.5 | AX16: =_xlfn.CONCAT(TEXT(C16,"mmm"),"-",AE16) -> Jun-2019 | AY16: =ROUNDUP(Table2[[#This Row],[Month]]/3,0) -> 2
A17: 16 | B17: =COUNTIF(R:R,R17) -> 10 | C17: 43636 | D17: =SUM(Table2[[#This Row],[Gray Min]:[Red Min]]) -> 57.133333 | E17: 10 | F17: 663 | G17: 131 | H17: 172 | I17: 8.6 | J17: 25.5 | K17: 12.666667 | L17: 10.266667 | M17: 0.1 | N17: Dunn Lorring, VA | O17: 4:30PM | P17: Audrey | Q17: =C17-C16 -> 2 | R17: =MONTH(C17)&"-"&YEAR(C17) -> 6-2019 | T17: =IF(WEEKDAY(C17)=1,"Sunday",IF(WEEKDAY(C17)=2,"Monday",IF(WEEKDAY(C17)=3,"Tuesday",IF(WEEKDAY(C17)=4,"Wednesday",IF(WEEKDAY(C17)=5,"Thursday",IF(WEEKDAY(C17)=6,"Friday","Saturday")))))) -> Thursday | U17: =IF(E17>=12,1,0) -> 0 | V17: =IFERROR(Table2[[#This Row],[Gray Min]]/Table2[[#This Row],[ClassLength]],"") -> 0.15052509 | W17: =IFERROR(Table2[[#This Row],[Blue Min]]/Table2[[#This Row],[ClassLength]],"") -> 0.44632439 | X17: =IFERROR(Table2[[#This Row],[Green Min]]/Table2[[#This Row],[ClassLength]],"") -> 0.22170362 | Y17: =IFERROR(Table2[[#This Row],[Orange Min]]/Table2[[#This Row],[ClassLength]],"") -> 0.17969662 | Z17: =IFERROR(Table2[[#This Row],[Red Min]]/Table2[[#This Row],[ClassLength]],"") -> 0.0017502917 | AA17: 232.14 | AB17: =AA17/B17 -> 23.214 | AC17: =AVERAGEIF(R:R,R17,F:F) -> 669.6 | AD17: =AVERAGEIF(R:R,R17,E:E) -> 10.2 | AE17: =YEAR(C17) -> 2019 | AG17: 12 | AH17: =F17/D17 -> 11.604434 | AI17: =RIGHT(O17,2) -> PM | AJ17: =R17&"-"&WEEKNUM(C17,1)-WEEKNUM(DATE(YEAR(C17),MONTH(C17),1),1)+1 -> 6-2019-4 | AK17: =MONTH(C17) -> 6 | AL17: =IFERROR(Table2[[#This Row],[Calories]]/Table2[[#This Row],[Splat]],"") -> 66.3 | AM17: =COUNTIF(N$2:$N$938,N17) -> 35 | AN17: =VLOOKUP(N17,'Helpful Tables'!A:D,4,FALSE) -> Virginia | AO17: =COUNTIF(AN:AN,Table2[[#This Row],[State]])/COUNTA(AN:AN) -> 0.056503198 | AP17: =VLOOKUP(N17,'Helpful Tables'!A:B,2,FALSE) -> 38.881885 | AQ17: =VLOOKUP(N17,'Helpful Tables'!A:C,3,FALSE) -> -77.229702 | AR17: =COUNTIF(P$2:$P$938,P17) -> 13 | AS17: {=_xlfn.IFS(E17<6,((E17/D17)*60)*0.5,AND(E17>=6,E17<9),((E17/D17)*60)*0.75,AND(E17>=9,E17<=11),((E17/D17)*60)*0.9,AND(E17=12),((E17/D17)*60)*1,AND(E17>=13,E17<=15),((E17/D17)*60)*1.2,AND(E17>=16,E17<=19),((E17/D17)*60)*1.5,E17>=20,((E17/D17)*60)*1.8)} -> 9.4515753 | AT17: {=_xlfn.IFS(F17<550,((F17/D17)*60)*0.5,AND(F17>=550,F17<575),((F17/D17)*60)*0.75,AND(F17>=575,F17<600),((F17/D17)*60)*0.9,AND(F17=600),((F17/D17)*60)*1,AND(F17>=601,F17<=625),((F17/D17)*60)*1.2,AND(F17>=626,F17<=650),((F17/D17)*60)*1.5,F17>=651,((F17/D17)*60)*1.8)} -> 1253.2789 | AU17: =(I17*-1.2)+(J17*-1.1)+(K17*1.2)+(L17*1.3)+(M17*1.5) -> -9.6733333 | AV17: =(AS17*0.4)+(AT17*0.4)+(AU17*0.2) -> 503.15752 | AW17: =PERCENTRANK(AV:AV,AV17)*100 -> 81.2 | AX17: =_xlfn.CONCAT(TEXT(C17,"mmm"),"-",AE17) -> Jun-2019 | AY17: =ROUNDUP(Table2[[#This Row],[Month]]/3,0) -> 2
A18: 17 | B18: =COUNTIF(R:R,R18) -> 10 | C18: 43638 | D18: =SUM(Table2[[#This Row],[Gray Min]:[Red Min]]) -> 61.933333 | E18: 9 | F18: 702 | G18: 130 | H18: 167 | I18: 12.416667 | J18: 22.8 | K18: 18.2 | L18: 8.5166667 | M18: 0 | N18: Foggy Bottom, DC | O18: 8:30AM | P18: Damani | Q18: =C18-C17 -> 2 | R18: =MONTH(C18)&"-"&YEAR(C18) -> 6-2019 | T18: =IF(WEEKDAY(C18)=1,"Sunday",IF(WEEKDAY(C18)=2,"Monday",IF(WEEKDAY(C18)=3,"Tuesday",IF(WEEKDAY(C18)=4,"Wednesday",IF(WEEKDAY(C18)=5,"Thursday",IF(WEEKDAY(C18)=6,"Friday","Saturday")))))) -> Saturday | U18: =IF(E18>=12,1,0) -> 0 | V18: =IFERROR(Table2[[#This Row],[Gray Min]]/Table2[[#This Row],[ClassLength]],"") -> 0.20048439 | W18: =IFERROR(Table2[[#This Row],[Blue Min]]/Table2[[#This Row],[ClassLength]],"") -> 0.36813778 | X18: =IFERROR(Table2[[#This Row],[Green Min]]/Table2[[#This Row],[ClassLength]],"") -> 0.29386437 | Y18: =IFERROR(Table2[[#This Row],[Orange Min]]/Table2[[#This Row],[ClassLength]],"") -> 0.13751346 | Z18: =IFERROR(Table2[[#This Row],[Red Min]]/Table2[[#This Row],[ClassLength]],"") -> 0 | AA18: 232.14 | AB18: =AA18/B18 -> 23.214 | AC18: =AVERAGEIF(R:R,R18,F:F) -> 669.6 | AD18: =AVERAGEIF(R:R,R18,E:E) -> 10.2 | AE18: =YEAR(C18) -> 2019 | AG18: 12 | AH18: =F18/D18 -> 11.334769 | AI18: =RIGHT(O18,2) -> AM | AJ18: =R18&"-"&WEEKNUM(C18,1)-WEEKNUM(DATE(YEAR(C18),MONTH(C18),1),1)+1 -> 6-2019-4 | AK18: =MONTH(C18) -> 6 | AL18: =IFERROR(Table2[[#This Row],[Calories]]/Table2[[#This Row],[Splat]],"") -> 78 | AM18: =COUNTIF(N$2:$N$938,N18) -> 38 | AN18: =VLOOKUP(N18,'Helpful Tables'!A:D,4,FALSE) -> Washington, DC | AO18: =COUNTIF(AN:AN,Table2[[#This Row],[State]])/COUNTA(AN:AN) -> 0.54904051 | AP18: =VLOOKUP(N18,'Helpful Tables'!A:B,2,FALSE) -> 38.90351 | AQ18: =VLOOKUP(N18,'Helpful Tables'!A:C,3,FALSE) -> -77.051809 | AR18: =COUNTIF(P$2:$P$938,P18) -> 20 | AS18: {=_xlfn.IFS(E18<6,((E18/D18)*60)*0.5,AND(E18>=6,E18<9),((E18/D18)*60)*0.75,AND(E18>=9,E18<=11),((E18/D18)*60)*0.9,AND(E18=12),((E18/D18)*60)*1,AND(E18>=13,E18<=15),((E18/D18)*60)*1.2,AND(E18>=16,E18<=19),((E18/D18)*60)*1.5,E18>=20,((E18/D18)*60)*1.8)} -> 7.8471475 | AT18: {=_xlfn.IFS(F18<550,((F18/D18)*60)*0.5,AND(F18>=550,F18<575),((F18/D18)*60)*0.75,AND(F18>=575,F18<600),((F18/D18)*60)*0.9,AND(F18=600),((F18/D18)*60)*1,AND(F18>=601,F18<=625),((F18/D18)*60)*1.2,AND(F18>=626,F18<=650),((F18/D18)*60)*1.5,F18>=651,((F18/D18)*60)*1.8)} -> 1224.155 | AU18: =(I18*-1.2)+(J18*-1.1)+(K18*1.2)+(L18*1.3)+(M18*1.5) -> -7.0683333 | AV18: =(AS18*0.4)+(AT18*0.4)+(AU18*0.2) -> 491.38719 | AW18: =PERCENTRANK(AV:AV,AV18)*100 -> 74.7 | AX18: =_xlfn.CONCAT(TEXT(C18,"mmm"),"-",AE18) -> Jun-2019 | AY18: =ROUNDUP(Table2[[#This Row],[Month]]/3,0) -> 2
A19: 18 | B19: =COUNTIF(R:R,R19) -> 10 | C19: 43641 | D19: =SUM(Table2[[#This Row],[Gray Min]:[Red Min]]) -> 60.55 | E19: 8 | F19: 681 | G19: 129 | H19: 173 | I19: 17.416667 | J19: 16.833333 | K19: 17.516667 | L19: 8.3166667 | M19: 0.46666667 | N19: 14th Street, DC | O19: 5:30PM | P19: Tiffany | Q19: =C19-C18 -> 3 | R19: =MONTH(C19)&"-"&YEAR(C19) -> 6-2019 | S19: Orange 3G | T19: =IF(WEEKDAY(C19)=1,"Sunday",IF(WEEKDAY(C19)=2,"Monday",IF(WEEKDAY(C19)=3,"Tuesday",IF(WEEKDAY(C19)=4,"Wednesday",IF(WEEKDAY(C19)=5,"Thursday",IF(WEEKDAY(C19)=6,"Friday","Saturday")))))) -> Tuesday | U19: =IF(E19>=12,1,0) -> 0 | V19: =IFERROR(Table2[[#This Row],[Gray Min]]/Table2[[#This Row],[ClassLength]],"") -> 0.28764107 | W19: =IFERROR(Table2[[#This Row],[Blue Min]]/Table2[[#This Row],[ClassLength]],"") -> 0.27800716 | X19: =IFERROR(Table2[[#This Row],[Green Min]]/Table2[[#This Row],[ClassLength]],"") -> 0.2892926 | Y19: =IFERROR(Table2[[#This Row],[Orange Min]]/Table2[[#This Row],[ClassLength]],"") -> 0.13735205 | Z19: =IFERROR(Table2[[#This Row],[Red Min]]/Table2[[#This Row],[ClassLength]],"") -> 0.0077071291 | AA19: 232.14 | AB19: =AA19/B19 -> 23.214 | AC19: =AVERAGEIF(R:R,R19,F:F) -> 669.6 | AD19: =AVERAGEIF(R:R,R19,E:E) -> 10.2 | AE19: =YEAR(C19) -> 2019 | AG19: 12 | AH19: =F19/D19 -> 11.246903 | AI19: =RIGHT(O19,2) -> PM | AJ19: =R19&"-"&WEEKNUM(C19,1)-WEEKNUM(DATE(YEAR(C19),MONTH(C19),1),1)+1 -> 6-2019-5 | AK19: =MONTH(C19) -> 6 | AL19: =IFERROR(Table2[[#This Row],[Calories]]/Table2[[#This Row],[Splat]],"") -> 85.125 | AM19: =COUNTIF(N$2:$N$938,N19) -> 48 | AN19: =VLOOKUP(N19,'Helpful Tables'!A:D,4,FALSE) -> Washington, DC | AO19: =COUNTIF(AN:AN,Table2[[#This Row],[State]])/COUNTA(AN:AN) -> 0.54904051 | AP19: =VLOOKUP(N19,'Helpful Tables'!A:B,2,FALSE) -> 38.916487 | AQ19: =VLOOKUP(N19,'Helpful Tables'!A:C,3,FALSE) -> -77.031514 | AR19: =COUNTIF(P$2:$P$938,P19) -> 30 | AS19: {=_xlfn.IFS(E19<6,((E19/D19)*60)*0.5,AND(E19>=6,E19<9),((E19/D19)*60)*0.75,AND(E19>=9,E19<=11),((E19/D19)*60)*0.9,AND(E19=12),((E19/D19)*60)*1,AND(E19>=13,E19<=15),((E19/D19)*60)*1.2,AND(E19>=16,E19<=19),((E19/D19)*60)*1.5,E19>=20,((E19/D19)*60)*1.8)} -> 5.9454996 | AT19: {=_xlfn.IFS(F19<550,((F19/D19)*60)*0.5,AND(F19>=550,F19<575),((F19/D19)*60)*0.75,AND(F19>=575,F19<600),((F19/D19)*60)*0.9,AND(F19=600),((F19/D19)*60)*1,AND(F19>=601,F19<=625),((F19/D19)*60)*1.2,AND(F19>=626,F19<=650),((F19/D19)*60)*1.5,F19>=651,((F19/D19)*60)*1.8)} -> 1214.6656 | AU19: =(I19*-1.2)+(J19*-1.1)+(K19*1.2)+(L19*1.3)+(M19*1.5) -> -6.885 | AV19: =(AS19*0.4)+(AT19*0.4)+(AU19*0.2) -> 486.86743 | AW19: =PERCENTRANK(AV:AV,AV19)*100 -> 72.2 | AX19: =_xlfn.CONCAT(TEXT(C19,"mmm"),"-",AE19) -> Jun-2019 | AY19: =ROUNDUP(Table2[[#This Row],[Month]]/3,0) -> 2
A20: 19 | B20: =COUNTIF(R:R,R20) -> 10 | C20: 43643 | D20: =SUM(Table2[[#This Row],[Gray Min]:[Red Min]]) -> 56 | E20: 10 | F20: 684 | G20: 135 | H20: 170 | I20: 6.3666667 | J20: 19.45 | K20: 20.433333 | L20: 9.75 | M20: 0 | N20: Dunn Lorring, VA | O20: 4:30PM | P20: Audrey | Q20: =C20-C19 -> 2 | R20: =MONTH(C20)&"-"&YEAR(C20) -> 6-2019 | S20: Orange 60 Tornado | T20: =IF(WEEKDAY(C20)=1,"Sunday",IF(WEEKDAY(C20)=2,"Monday",IF(WEEKDAY(C20)=3,"Tuesday",IF(WEEKDAY(C20)=4,"Wednesday",IF(WEEKDAY(C20)=5,"Thursday",IF(WEEKDAY(C20)=6,"Friday","Saturday")))))) -> Thursday | U20: =IF(E20>=12,1,0) -> 0 | V20: =IFERROR(Table2[[#This Row],[Gray Min]]/Table2[[#This Row],[ClassLength]],"") -> 0.11369048 | W20: =IFERROR(Table2[[#This Row],[Blue Min]]/Table2[[#This Row],[ClassLength]],"") -> 0.34732143 | X20: =IFERROR(Table2[[#This Row],[Green Min]]/Table2[[#This Row],[ClassLength]],"") -> 0.36488095 | Y20: =IFERROR(Table2[[#This Row],[Orange Min]]/Table2[[#This Row],[ClassLength]],"") -> 0.17410714 | Z20: =IFERROR(Table2[[#This Row],[Red Min]]/Table2[[#This Row],[ClassLength]],"") -> 0 | AA20: 232.14 | AB20: =AA20/B20 -> 23.214 | AC20: =AVERAGEIF(R:R,R20,F:F) -> 669.6 | AD20: =AVERAGEIF(R:R,R20,E:E) -> 10.2 | AE20: =YEAR(C20) -> 2019 | AG20: 12 | AH20: =F20/D20 -> 12.214286 | AI20: =RIGHT(O20,2) -> PM | AJ20: =R20&"-"&WEEKNUM(C20,1)-WEEKNUM(DATE(YEAR(C20),MONTH(C20),1),1)+1 -> 6-2019-5 | AK20: =MONTH(C20) -> 6 | AL20: =IFERROR(Table2[[#This Row],[Calories]]/Table2[[#This Row],[Splat]],"") -> 68.4 | AM20: =COUNTIF(N$2:$N$938,N20) -> 35 | AN20: =VLOOKUP(N20,'Helpful Tables'!A:D,4,FALSE) -> Virginia | AO20: =COUNTIF(AN:AN,Table2[[#This Row],[State]])/COUNTA(AN:AN) -> 0.056503198 | AP20: =VLOOKUP(N20,'Helpful Tables'!A:B,2,FALSE) -> 38.881885 | AQ20: =VLOOKUP(N20,'Helpful Tables'!A:C,3,FALSE) -> -77.229702 | AR20: =COUNTIF(P$2:$P$938,P20) -> 13 | AS20: {=_xlfn.IFS(E20<6,((E20/D20)*60)*0.5,AND(E20>=6,E20<9),((E20/D20)*60)*0.75,AND(E20>=9,E20<=11),((E20/D20)*60)*0.9,AND(E20=12),((E20/D20)*60)*1,AND(E20>=13,E20<=15),((E20/D20)*60)*1.2,AND(E20>=16,E20<=19),((E20/D20)*60)*1.5,E20>=20,((E20/D20)*60)*1.8)} -> 9.6428571 | AT20: {=_xlfn.IFS(F20<550,((F20/D20)*60)*0.5,AND(F20>=550,F20<575),((F20/D20)*60)*0.75,AND(F20>=575,F20<600),((F20/D20)*60)*0.9,AND(F20=600),((F20/D20)*60)*1,AND(F20>=601,F20<=625),((F20/D20)*60)*1.2,AND(F20>=626,F20<=650),((F20/D20)*60)*1.5,F20>=651,((F20/D20)*60)*1.8)} -> 1319.1429 | AU20: =(I20*-1.2)+(J20*-1.1)+(K20*1.2)+(L20*1.3)+(M20*1.5) -> 8.16 | AV20: =(AS20*0.4)+(AT20*0.4)+(AU20*0.2) -> 533.14629 | AW20: =PERCENTRANK(AV:AV,AV20)*100 -> 94.5 | AX20: =_xlfn.CONCAT(TEXT(C20,"mmm"),"-",AE20) -> Jun-2019 | AY20: =ROUNDUP(Table2[[#This Row],[Month]]/3,0) -> 2
A21: 20 | B21: =COUNTIF(R:R,R21) -> 10 | C21: 43645 | D21: =SUM(Table2[[#This Row],[Gray Min]:[Red Min]]) -> 55.833333 | E21: 9 | F21: 661 | G21: 133 | H21: 170 | I21: 8.3833333 | J21: 19.266667 | K21: 19.533333 | L21: 8.65 | M21: 0 | N21: 14th Street, DC | O21: 9:30AM | P21: Tiffany | Q21: =C21-C20 -> 2 | R21: =MONTH(C21)&"-"&YEAR(C21) -> 6-2019 | T21: =IF(WEEKDAY(C21)=1,"Sunday",IF(WEEKDAY(C21)=2,"Monday",IF(WEEKDAY(C21)=3,"Tuesday",IF(WEEKDAY(C21)=4,"Wednesday",IF(WEEKDAY(C21)=5,"Thursday",IF(WEEKDAY(C21)=6,"Friday","Saturday")))))) -> Saturday | U21: =IF(E21>=12,1,0) -> 0 | V21: =IFERROR(Table2[[#This Row],[Gray Min]]/Table2[[#This Row],[ClassLength]],"") -> 0.15014925 | W21: =IFERROR(Table2[[#This Row],[Blue Min]]/Table2[[#This Row],[ClassLength]],"") -> 0.34507463 | X21: =IFERROR(Table2[[#This Row],[Green Min]]/Table2[[#This Row],[ClassLength]],"") -> 0.34985075 | Y21: =IFERROR(Table2[[#This Row],[Orange Min]]/Table2[[#This Row],[ClassLength]],"") -> 0.15492537 | Z21: =IFERROR(Table2[[#This Row],[Red Min]]/Table2[[#This Row],[ClassLength]],"") -> 0 | AA21: 232.14 | AB21: =AA21/B21 -> 23.214 | AC21: =AVERAGEIF(R:R,R21,F:F) -> 669.6 | AD21: =AVERAGEIF(R:R,R21,E:E) -> 10.2 | AE21: =YEAR(C21) -> 2019 | AG21: 12 | AH21: =F21/D21 -> 11.838806 | AI21: =RIGHT(O21,2) -> AM | AJ21: =R21&"-"&WEEKNUM(C21,1)-WEEKNUM(DATE(YEAR(C21),MONTH(C21),1),1)+1 -> 6-2019-5 | AK21: =MONTH(C21) -> 6 | AL21: =IFERROR(Table2[[#This Row],[Calories]]/Table2[[#This Row],[Splat]],"") -> 73.444444 | AM21: =COUNTIF(N$2:$N$938,N21) -> 48 | AN21: =VLOOKUP(N21,'Helpful Tables'!A:D,4,FALSE) -> Washington, DC | AO21: =COUNTIF(AN:AN,Table2[[#This Row],[State]])/COUNTA(AN:AN) -> 0.54904051 | AP21: =VLOOKUP(N21,'Helpful Tables'!A:B,2,FALSE) -> 38.916487 | AQ21: =VLOOKUP(N21,'Helpful Tables'!A:C,3,FALSE) -> -77.031514 | AR21: =COUNTIF(P$2:$P$938,P21) -> 30 | AS21: {=_xlfn.IFS(E21<6,((E21/D21)*60)*0.5,AND(E21>=6,E21<9),((E21/D21)*60)*0.75,AND(E21>=9,E21<=11),((E21/D21)*60)*0.9,AND(E21=12),((E21/D21)*60)*1,AND(E21>=13,E21<=15),((E21/D21)*60)*1.2,AND(E21>=16,E21<=19),((E21/D21)*60)*1.5,E21>=20,((E21/D21)*60)*1.8)} -> 8.7044776 | AT21: {=_xlfn.IFS(F21<550,((F21/D21)*60)*0.5,AND(F21>=550,F21<575),((F21/D21)*60)*0.75,AND(F21>=575,F21<600),((F21/D21)*60)*0.9,AND(F21=600),((F21/D21)*60)*1,AND(F21>=601,F21<=625),((F21/D21)*60)*1.2,AND(F21>=626,F21<=650),((F21/D21)*60)*1.5,F21>=651,((F21/D21)*60)*1.8)} -> 1278.591 | AU21: =(I21*-1.2)+(J21*-1.1)+(K21*1.2)+(L21*1.3)+(M21*1.5) -> 3.4316667 | AV21: =(AS21*0.4)+(AT21*0.4)+(AU21*0.2) -> 515.60454 | AW21: =PERCENTRANK(AV:AV,AV21)*100 -> 88.5 | AX21: =_xlfn.CONCAT(TEXT(C21,"mmm"),"-",AE21) -> Jun-2019 | AY21: =ROUNDUP(Table2[[#This Row],[Month]]/3,0) -> 2
A22: 21 | B22: =COUNTIF(R:R,R22) -> 11 | C22: 43648 | D22: =SUM(Table2[[#This Row],[Gray Min]:[Red Min]]) -> 56.35 | E22: 17 | F22: 650 | G22: 132 | H22: 171 | I22: 8.1 | J22: 16.766667 | K22: 14.9 | L22: 8.9333333 | M22: 7.65 | N22: 14th Street, DC | O22: 5:30PM | P22: Tiffany | Q22: =C22-C21 -> 3 | R22: =MONTH(C22)&"-"&YEAR(C22) -> 7-2019 | S22: Orange 3G | T22: =IF(WEEKDAY(C22)=1,"Sunday",IF(WEEKDAY(C22)=2,"Monday",IF(WEEKDAY(C22)=3,"Tuesday",IF(WEEKDAY(C22)=4,"Wednesday",IF(WEEKDAY(C22)=5,"Thursday",IF(WEEKDAY(C22)=6,"Friday","Saturday")))))) -> Tuesday | U22: =IF(E22>=12,1,0) -> 1 | V22: =IFERROR(Table2[[#This Row],[Gray Min]]/Table2[[#This Row],[ClassLength]],"") -> 0.14374445 | W22: =IFERROR(Table2[[#This Row],[Blue Min]]/Table2[[#This Row],[ClassLength]],"") -> 0.29754511 | X22: =IFERROR(Table2[[#This Row],[Green Min]]/Table2[[#This Row],[ClassLength]],"") -> 0.26441881 | Y22: =IFERROR(Table2[[#This Row],[Orange Min]]/Table2[[#This Row],[ClassLength]],"") -> 0.15853298 | Z22: =IFERROR(Table2[[#This Row],[Red Min]]/Table2[[#This Row],[ClassLength]],"") -> 0.13575865 | AA22: 232.14 | AB22: =AA22/B22 -> 21.103636 | AC22: =AVERAGEIF(R:R,R22,F:F) -> 649.63636 | AD22: =AVERAGEIF(R:R,R22,E:E) -> 15.636364 | AE22: =YEAR(C22) -> 2019 | AG22: 12 | AH22: =F22/D22 -> 11.535049 | AI22: =RIGHT(O22,2) -> PM | AJ22: =R22&"-"&WEEKNUM(C22,1)-WEEKNUM(DATE(YEAR(C22),MONTH(C22),1),1)+1 -> 7-2019-1 | AK22: =MONTH(C22) -> 7 | AL22: =IFERROR(Table2[[#This Row],[Calories]]/Table2[[#This Row],[Splat]],"") -> 38.235294 | AM22: =COUNTIF(N$2:$N$938,N22) -> 48 | AN22: =VLOOKUP(N22,'Helpful Tables'!A:D,4,FALSE) -> Washington, DC | AO22: =COUNTIF(AN:AN,Table2[[#This Row],[State]])/COUNTA(AN:AN) -> 0.54904051 | AP22: =VLOOKUP(N22,'Helpful Tables'!A:B,2,FALSE) -> 38.916487 | AQ22: =VLOOKUP(N22,'Helpful Tables'!A:C,3,FALSE) -> -77.031514 | AR22: =COUNTIF(P$2:$P$938,P22) -> 30 | AS22: {=_xlfn.IFS(E22<6,((E22/D22)*60)*0.5,AND(E22>=6,E22<9),((E22/D22)*60)*0.75,AND(E22>=9,E22<=11),((E22/D22)*60)*0.9,AND(E22=12),((E22/D22)*60)*1,AND(E22>=13,E22<=15),((E22/D22)*60)*1.2,AND(E22>=16,E22<=19),((E22/D22)*60)*1.5,E22>=20,((E22/D22)*60)*1.8)} -> 27.15173 | AT22: {=_xlfn.IFS(F22<550,((F22/D22)*60)*0.5,AND(F22>=550,F22<575),((F22/D22)*60)*0.75,AND(F22>=575,F22<600),((F22/D22)*60)*0.9,AND(F22=600),((F22/D22)*60)*1,AND(F22>=601,F22<=625),((F22/D22)*60)*1.2,AND(F22>=626,F22<=650),((F22/D22)*60)*1.5,F22>=651,((F22/D22)*60)*1.8)} -> 1038.1544 | AU22: =(I22*-1.2)+(J22*-1.1)+(K22*1.2)+(L22*1.3)+(M22*1.5) -> 12.805 | AV22: =(AS22*0.4)+(AT22*0.4)+(AU22*0.2) -> 428.68345 | AW22: =PERCENTRANK(AV:AV,AV22)*100 -> 64.4 | AX22: =_xlfn.CONCAT(TEXT(C22,"mmm"),"-",AE22) -> Jul-2019 | AY22: =ROUNDUP(Table2[[#This Row],[Month]]/3,0) -> 3
A23: 22 | B23: =COUNTIF(R:R,R23) -> 11 | C23: 43649 | D23: =SUM(Table2[[#This Row],[Gray Min]:[Red Min]]) -> 62.283333 | E23: 12 | F23: 701 | G23: 129 | H23: 165 | I23: 10.65 | J23: 15.216667 | K23: 23.816667 | L23: 11.35 | M23: 1.25 | N23: 14th Street, DC | O23: 5:30PM | P23: Chuck | Q23: =C23-C22 -> 1 | R23: =MONTH(C23)&"-"&YEAR(C23) -> 7-2019 | S23: Orange 3G | T23: =IF(WEEKDAY(C23)=1,"Sunday",IF(WEEKDAY(C23)=2,"Monday",IF(WEEKDAY(C23)=3,"Tuesday",IF(WEEKDAY(C23)=4,"Wednesday",IF(WEEKDAY(C23)=5,"Thursday",IF(WEEKDAY(C23)=6,"Friday","Saturday")))))) -> Wednesday | U23: =IF(E23>=12,1,0) -> 1 | V23: =IFERROR(Table2[[#This Row],[Gray Min]]/Table2[[#This Row],[ClassLength]],"") -> 0.17099277 | W23: =IFERROR(Table2[[#This Row],[Blue Min]]/Table2[[#This Row],[ClassLength]],"") -> 0.24431362 | X23: =IFERROR(Table2[[#This Row],[Green Min]]/Table2[[#This Row],[ClassLength]],"") -> 0.38239229 | Y23: =IFERROR(Table2[[#This Row],[Orange Min]]/Table2[[#This Row],[ClassLength]],"") -> 0.18223174 | Z23: =IFERROR(Table2[[#This Row],[Red Min]]/Table2[[#This Row],[ClassLength]],"") -> 0.020069575 | AA23: 232.14 | AB23: =AA23/B23 -> 21.103636 | AC23: =AVERAGEIF(R:R,R23,F:F) -> 649.63636 | AD23: =AVERAGEIF(R:R,R23,E:E) -> 15.636364 | AE23: =YEAR(C23) -> 2019 | AG23: 12 | AH23: =F23/D23 -> 11.255017 | AI23: =RIGHT(O23,2) -> PM | AJ23: =R23&"-"&WEEKNUM(C23,1)-WEEKNUM(DATE(YEAR(C23),MONTH(C23),1),1)+1 -> 7-2019-1 | AK23: =MONTH(C23) -> 7 | AL23: =IFERROR(Table2[[#This Row],[Calories]]/Table2[[#This Row],[Splat]],"") -> 58.416667 | AM23: =COUNTIF(N$2:$N$938,N23) -> 48 | AN23: =VLOOKUP(N23,'Helpful Tables'!A:D,4,FALSE) -> Washington, DC | AO23: =COUNTIF(AN:AN,Table2[[#This Row],[State]])/COUNTA(AN:AN) -> 0.54904051 | AP23: =VLOOKUP(N23,'Helpful Tables'!A:B,2,FALSE) -> 38.916487 | AQ23: =VLOOKUP(N23,'Helpful Tables'!A:C,3,FALSE) -> -77.031514 | AR23: =COUNTIF(P$2:$P$938,P23) -> 1 | AS23: {=_xlfn.IFS(E23<6,((E23/D23)*60)*0.5,AND(E23>=6,E23<9),((E23/D23)*60)*0.75,AND(E23>=9,E23<=11),((E23/D23)*60)*0.9,AND(E23=12),((E23/D23)*60)*1,AND(E23>=13,E23<=15),((E23/D23)*60)*1.2,AND(E23>=16,E23<=19),((E23/D23)*60)*1.5,E23>=20,((E23/D23)*60)*1.8)} -> 11.560075 | AT23: {=_xlfn.IFS(F23<550,((F23/D23)*60)*0.5,AND(F23>=550,F23<575),((F23/D23)*60)*0.75,AND(F23>=575,F23<600),((F23/D23)*60)*0.9,AND(F23=600),((F23/D23)*60)*1,AND(F23>=601,F23<=625),((F23/D23)*60)*1.2,AND(F23>=626,F23<=650),((F23/D23)*60)*1.5,F23>=651,((F23/D23)*60)*1.8)} -> 1215.5419 | AU23: =(I23*-1.2)+(J23*-1.1)+(K23*1.2)+(L23*1.3)+(M23*1.5) -> 15.691667 | AV23: =(AS23*0.4)+(AT23*0.4)+(AU23*0.2) -> 493.97911 | AW23: =PERCENTRANK(AV:AV,AV23)*100 -> 75.6 | AX23: =_xlfn.CONCAT(TEXT(C23,"mmm"),"-",AE23) -> Jul-2019 | AY23: =ROUNDUP(Table2[[#This Row],[Month]]/3,0) -> 3
